Workbook

Sheet 使用说明
A1: コインランドリー｜地理信息漏斗选址缩圈评分表（中文版）
A3: 导入 Google 表格后按以下步骤使用（本文件已预置公式到第204行；需要更多行可向下填充）：
A4: 1）在「候选点」表，从第5行开始：每行输入一个候选点（网格中心/商圈中心点）。先填：编号、区域名称、纬度、经度。
A5: 2）逐步补齐原始数据列（例如：600m内户数、2km内户数、竞品数量、租金坪单价等）。
A6: 3）评分列会自动把原始数据转换成 1~5 分（按 80/60/40/20 分位阈值）。当同一指标至少有 2 个候选点填了数值时才会开始出分（避免报错）。
A7: 4）先看「一票否决」：显示「淘汰」的点位直接剔除；再按「都市型总分」或「郊外型总分」排序取前20。
A8: 5）前20 往往集中在少数片区：建议按地理位置聚类，合并成前5~10商圈后，再进入线下验证（上下水/电力/排风/24h等属于下一阶段硬闸门）。
A9: 6）如需超过预置行数：复制最后一行的评分/总分公式单元格并向下填充即可。
A12: 表结构说明：
A13: 「指标字典」：指标定义、打分方向、两套权重、以及地理信息缩圈阶段的一票否决规则（权重可自行调整）。
A14: 「分位数阈值」：根据候选点数据自动计算每个指标的 80/60/40/20 分位阈值。
A15: 「候选点」：输入原始数据 → 自动评分 → 自动计算两套权重总分 → 得到地理信息缩圈结果。
A17: 注意：本表用于“地理信息缩圈”，不代替最终物件施工可行性判断与合同尽调。

Sheet 指标字典
A1: 指标ID | B1: 阶段 | C1: 类别 | D1: 指标名称 | E1: 圈层 | F1: 原始字段（候选点表） | G1: 单位 | H1: 方向（高=好/低=好） | I1: 打分规则（说明） | J1: 都市型权重 | K1: 郊外型权重 | L1: 都市型一票否决（缩圈） | M1: 郊外型一票否决（缩圈） | N1: 备注
A2: D01 | B2: 地理信息 | C2: 需求 | D2: 600m内户数（世帯数） | E2: 600m | F2: 600m内户数 | G2: 户 | H2: 高=好 | I2: 分位数阈值法：>=80分位=5；>=60分位=4；>=40分位=3；>=20分位=2；否则=1 | J2: 15 | K2: 8 | L2: 若评分=1则淘汰 | N2: 住宅需求核心
A3: D02 | B3: 地理信息 | C3: 需求 | D3: 2km内户数（世帯数） | E3: 2km | F3: 2km内户数 | G3: 户 | H3: 高=好 | I3: 分位数阈值法（同上） | J3: 0 | K3: 15 | M3: 若评分=1则淘汰 | N3: 郊外型主要商圈
A4: D03 | B4: 地理信息 | C4: 需求 | D4: 600m内租赁户占比 | E4: 600m | F4: 600m内租赁户占比 | G4: % | H4: 高=好 | I4: 分位数阈值法（同上） | J4: 10 | K4: 0 | N4: 租赁多常对应小户型/无洗衣条件（代理指标）
A5: D04 | B5: 地理信息 | C5: 需求 | D5: 2km内租赁户占比 | E5: 2km | F5: 2km内租赁户占比 | G5: % | H5: 高=好 | I5: 分位数阈值法（同上） | J5: 0 | K5: 5 | N5: 郊外也保留少量权重
A6: D05 | B6: 地理信息 | C6: 需求 | D6: 600m内集合住宅占比 | E6: 600m | F6: 600m内集合住宅占比 | G6: % | H6: 高=好 | I6: 分位数阈值法（同上） | J6: 8 | K6: 0 | N6: 公寓密度代理
A7: D06 | B7: 地理信息 | C7: 需求 | D7: 600m内小户型占比（单身+2人户） | E7: 600m | F7: 600m内小户型占比 | G7: % | H7: 高=好 | I7: 分位数阈值法（同上） | J7: 6 | K7: 0 | N7: 更贴近都市型画像（代理指标）
A8: D07 | B8: 地理信息 | C8: 需求 | D8: 2km内家庭户占比 | E8: 2km | F8: 2km内家庭户占比 | G8: % | H8: 高=好 | I8: 分位数阈值法（同上） | J8: 0 | K8: 5 | N8: 郊外型更相关（代理指标）
A9: D08 | B9: 地理信息 | C9: 需求 | D9: 人口/户数趋势指数（区域） | E9: 区域 | F9: 人口趋势指数 | G9: 指数 | H9: 高=好 | I9: 分位数阈值法（同上；拿不到可先填3） | J9: 6 | K9: 5 | N9: 用于趋势代理（RESAS等）
A10: C01 | B10: 地理信息 | C10: 竞争 | D10: 600m内竞品数量 | E10: 600m | F10: 600m内竞品数量 | G10: 家 | H10: 低=好 | I10: 反向分位数阈值法：<=20分位=5；<=40分位=4；<=60分位=3；<=80分位=2；否则=1 | J10: 10 | K10: 0 | L10: 若评分=1且D01<=2可考虑淘汰 | N10: 密集竞争会挤压卖上
A11: C02 | B11: 地理信息 | C11: 竞争 | D11: 2km内竞品数量 | E11: 2km | F11: 2km内竞品数量 | G11: 家 | H11: 低=好 | I11: 反向分位数阈值法（同上） | J11: 7 | K11: 10 | M11: 若评分=1且D02<=2可考虑淘汰 | N11: 郊外圈竞争更关键
A12: C03 | B12: 地图 | C12: 竞争 | D12: 600m内是否存在强竞品（0/1） | E12: 600m | F12: 600m内强竞品(0/1) | G12: 0/1 | H12: 低=好 | I12: 二值：有=1分；无=5分 | J12: 8 | K12: 0 | L12: 若=1则淘汰 | N12: 强竞品：评价数高/规模大/设备新/停车强等
A13: C04 | B13: 地图 | C13: 竞争 | D13: 2km内是否存在强竞品（0/1） | E13: 2km | F13: 2km内强竞品(0/1) | G13: 0/1 | H13: 低=好 | I13: 二值：有=1分；无=5分 | J13: 0 | K13: 8 | M13: 若=1且C02=1可淘汰 | N13: 强竞品+高密度组合风险
A14: C05 | B14: 地理信息 | C14: 竞争 | D14: 最近竞品距离（米） | E14: - | F14: 最近竞品距离(米) | G14: 米 | H14: 高=好 | I14: 分位数阈值法（同上） | J14: 0 | K14: 4 | N14: 郊外型越远越好（可选）
A15: A01 | B15: 地理信息 | C15: 可达 | D15: 到最近车站距离（米） | E15: - | F15: 到最近车站距离(米) | G15: 米 | H15: 低=好 | I15: 反向分位数阈值法（同上） | J15: 8 | K15: 0 | N15: 都市型更看重步行可达
A16: A02 | B16: 地理信息 | C16: 可达 | D16: 到生活锚点距离（米：超市/药妆/家居） | E16: - | F16: 到生活锚点距离(米) | G16: 米 | H16: 低=好 | I16: 反向分位数阈值法（同上） | J16: 6 | K16: 5 | N16: 锚点=顺路洗/等洗理由
A17: A03 | B17: 地理信息 | C17: 可达 | D17: 到主干道距离（米） | E17: - | F17: 到主干道距离(米) | G17: 米 | H17: 低=好 | I17: 反向分位数阈值法（同上） | J17: 0 | K17: 8 | M17: 若评分=1可淘汰（郊外） | N17: 郊外型车流可达性关键
A18: A04 | B18: 地图 | C18: 可达 | D18: 300m内是否有大型地面停车锚点（0/1） | E18: 300m | F18: 300m内停车锚点(0/1) | G18: 0/1 | H18: 高=好 | I18: 二值：有=5分；无=1分 | J18: 0 | K18: 8 | N18: 郊外停车代理（大超市/ホームセンター等）
A19: A05 | B19: 地图 | C19: 可达 | D19: 可视性/沿街性评分（1-5） | E19: - | F19: 可视性评分(1-5) | G19: 分 | H19: 高=好 | I19: 人工评分：5=沿街显眼；1=隐藏/二楼 | J19: 6 | K19: 4 | N19: 建议前50后再打分
A20: K01 | B20: 地理信息 | C20: 成本 | D20: 租金单价估计（円/坪） | E20: - | F20: 坪租估计(円/坪) | G20: 円/坪 | H20: 低=好 | I20: 反向分位数阈值法（同上） | J20: 8 | K20: 10 | L20: 若评分=1则淘汰 | M20: 若评分=1则淘汰 | N20: 缩圈阶段可用该区物件抽样估计
A21: R01 | B21: 地图 | C21: 风险 | D21: 商圈阻隔风险评分（1-5） | E21: 600m | F21: 阻隔评分(1-5) | G21: 分 | H21: 高=好 | I21: 人工评分：5=无明显阻隔；1=铁路/河流切割 | J21: 2 | K21: 2 | N21: 前20线下核验更准
A22: R02 | B22: 现场 | C22: 风险 | D22: 夜间邻避/治安风险评分（1-5） | E22: - | F22: 夜间风险评分(1-5) | G22: 分 | H22: 高=好 | I22: 人工评分：5=低风险 | J22: 0 | K22: 3 | N22: 缩圈可先留空；前20线下补齐

Sheet 分位数阈值
A1: 指标ID | B1: 原始列（候选点） | C1: 方向 | D1: 80分位阈值 | E1: 60分位阈值 | F1: 40分位阈值 | G1: 20分位阈值 | H1: 备注
A2: D01 | B2: E | C2: 高=好 | D2: =IF(COUNT('候选点'!$E$5:$E$304)<2,"",_xlfn.PERCENTILE.INC('候选点'!$E$5:$E$304,0.8)) | E2: =IF(COUNT('候选点'!$E$5:$E$304)<2,"",_xlfn.PERCENTILE.INC('候选点'!$E$5:$E$304,0.6)) | F2: =IF(COUNT('候选点'!$E$5:$E$304)<2,"",_xlfn.PERCENTILE.INC('候选点'!$E$5:$E$304,0.4)) | G2: =IF(COUNT('候选点'!$E$5:$E$304)<2,"",_xlfn.PERCENTILE.INC('候选点'!$E$5:$E$304,0.2)) | H2: 600m内户数
A3: D02 | B3: F | C3: 高=好 | D3: =IF(COUNT('候选点'!$F$5:$F$304)<2,"",_xlfn.PERCENTILE.INC('候选点'!$F$5:$F$304,0.8)) | E3: =IF(COUNT('候选点'!$F$5:$F$304)<2,"",_xlfn.PERCENTILE.INC('候选点'!$F$5:$F$304,0.6)) | F3: =IF(COUNT('候选点'!$F$5:$F$304)<2,"",_xlfn.PERCENTILE.INC('候选点'!$F$5:$F$304,0.4)) | G3: =IF(COUNT('候选点'!$F$5:$F$304)<2,"",_xlfn.PERCENTILE.INC('候选点'!$F$5:$F$304,0.2)) | H3: 2km内户数
A4: D03 | B4: G | C4: 高=好 | D4: =IF(COUNT('候选点'!$G$5:$G$304)<2,"",_xlfn.PERCENTILE.INC('候选点'!$G$5:$G$304,0.8)) | E4: =IF(COUNT('候选点'!$G$5:$G$304)<2,"",_xlfn.PERCENTILE.INC('候选点'!$G$5:$G$304,0.6)) | F4: =IF(COUNT('候选点'!$G$5:$G$304)<2,"",_xlfn.PERCENTILE.INC('候选点'!$G$5:$G$304,0.4)) | G4: =IF(COUNT('候选点'!$G$5:$G$304)<2,"",_xlfn.PERCENTILE.INC('候选点'!$G$5:$G$304,0.2)) | H4: 600m租赁户占比
A5: D04 | B5: H | C5: 高=好 | D5: =IF(COUNT('候选点'!$H$5:$H$304)<2,"",_xlfn.PERCENTILE.INC('候选点'!$H$5:$H$304,0.8)) | E5: =IF(COUNT('候选点'!$H$5:$H$304)<2,"",_xlfn.PERCENTILE.INC('候选点'!$H$5:$H$304,0.6)) | F5: =IF(COUNT('候选点'!$H$5:$H$304)<2,"",_xlfn.PERCENTILE.INC('候选点'!$H$5:$H$304,0.4)) | G5: =IF(COUNT('候选点'!$H$5:$H$304)<2,"",_xlfn.PERCENTILE.INC('候选点'!$H$5:$H$304,0.2)) | H5: 2km租赁户占比
A6: D05 | B6: I | C6: 高=好 | D6: =IF(COUNT('候选点'!$I$5:$I$304)<2,"",_xlfn.PERCENTILE.INC('候选点'!$I$5:$I$304,0.8)) | E6: =IF(COUNT('候选点'!$I$5:$I$304)<2,"",_xlfn.PERCENTILE.INC('候选点'!$I$5:$I$304,0.6)) | F6: =IF(COUNT('候选点'!$I$5:$I$304)<2,"",_xlfn.PERCENTILE.INC('候选点'!$I$5:$I$304,0.4)) | G6: =IF(COUNT('候选点'!$I$5:$I$304)<2,"",_xlfn.PERCENTILE.INC('候选点'!$I$5:$I$304,0.2)) | H6: 600m集合住宅占比
A7: D06 | B7: J | C7: 高=好 | D7: =IF(COUNT('候选点'!$J$5:$J$304)<2,"",_xlfn.PERCENTILE.INC('候选点'!$J$5:$J$304,0.8)) | E7: =IF(COUNT('候选点'!$J$5:$J$304)<2,"",_xlfn.PERCENTILE.INC('候选点'!$J$5:$J$304,0.6)) | F7: =IF(COUNT('候选点'!$J$5:$J$304)<2,"",_xlfn.PERCENTILE.INC('候选点'!$J$5:$J$304,0.4)) | G7: =IF(COUNT('候选点'!$J$5:$J$304)<2,"",_xlfn.PERCENTILE.INC('候选点'!$J$5:$J$304,0.2)) | H7: 600m小户型占比
A8: D07 | B8: K | C8: 高=好 | D8: =IF(COUNT('候选点'!$K$5:$K$304)<2,"",_xlfn.PERCENTILE.INC('候选点'!$K$5:$K$304,0.8)) | E8: =IF(COUNT('候选点'!$K$5:$K$304)<2,"",_xlfn.PERCENTILE.INC('候选点'!$K$5:$K$304,0.6)) | F8: =IF(COUNT('候选点'!$K$5:$K$304)<2,"",_xlfn.PERCENTILE.INC('候选点'!$K$5:$K$304,0.4)) | G8: =IF(COUNT('候选点'!$K$5:$K$304)<2,"",_xlfn.PERCENTILE.INC('候选点'!$K$5:$K$304,0.2)) | H8: 2km家庭户占比
A9: D08 | B9: L | C9: 高=好 | D9: =IF(COUNT('候选点'!$L$5:$L$304)<2,"",_xlfn.PERCENTILE.INC('候选点'!$L$5:$L$304,0.8)) | E9: =IF(COUNT('候选点'!$L$5:$L$304)<2,"",_xlfn.PERCENTILE.INC('候选点'!$L$5:$L$304,0.6)) | F9: =IF(COUNT('候选点'!$L$5:$L$304)<2,"",_xlfn.PERCENTILE.INC('候选点'!$L$5:$L$304,0.4)) | G9: =IF(COUNT('候选点'!$L$5:$L$304)<2,"",_xlfn.PERCENTILE.INC('候选点'!$L$5:$L$304,0.2)) | H9: 人口趋势指数
A10: C01 | B10: M | C10: 低=好 | D10: =IF(COUNT('候选点'!$M$5:$M$304)<2,"",_xlfn.PERCENTILE.INC('候选点'!$M$5:$M$304,0.8)) | E10: =IF(COUNT('候选点'!$M$5:$M$304)<2,"",_xlfn.PERCENTILE.INC('候选点'!$M$5:$M$304,0.6)) | F10: =IF(COUNT('候选点'!$M$5:$M$304)<2,"",_xlfn.PERCENTILE.INC('候选点'!$M$5:$M$304,0.4)) | G10: =IF(COUNT('候选点'!$M$5:$M$304)<2,"",_xlfn.PERCENTILE.INC('候选点'!$M$5:$M$304,0.2)) | H10: 600m竞品数量
A11: C02 | B11: N | C11: 低=好 | D11: =IF(COUNT('候选点'!$N$5:$N$304)<2,"",_xlfn.PERCENTILE.INC('候选点'!$N$5:$N$304,0.8)) | E11: =IF(COUNT('候选点'!$N$5:$N$304)<2,"",_xlfn.PERCENTILE.INC('候选点'!$N$5:$N$304,0.6)) | F11: =IF(COUNT('候选点'!$N$5:$N$304)<2,"",_xlfn.PERCENTILE.INC('候选点'!$N$5:$N$304,0.4)) | G11: =IF(COUNT('候选点'!$N$5:$N$304)<2,"",_xlfn.PERCENTILE.INC('候选点'!$N$5:$N$304,0.2)) | H11: 2km竞品数量
A12: C05 | B12: O | C12: 高=好 | D12: =IF(COUNT('候选点'!$O$5:$O$304)<2,"",_xlfn.PERCENTILE.INC('候选点'!$O$5:$O$304,0.8)) | E12: =IF(COUNT('候选点'!$O$5:$O$304)<2,"",_xlfn.PERCENTILE.INC('候选点'!$O$5:$O$304,0.6)) | F12: =IF(COUNT('候选点'!$O$5:$O$304)<2,"",_xlfn.PERCENTILE.INC('候选点'!$O$5:$O$304,0.4)) | G12: =IF(COUNT('候选点'!$O$5:$O$304)<2,"",_xlfn.PERCENTILE.INC('候选点'!$O$5:$O$304,0.2)) | H12: 最近竞品距离
A13: A01 | B13: R | C13: 低=好 | D13: =IF(COUNT('候选点'!$R$5:$R$304)<2,"",_xlfn.PERCENTILE.INC('候选点'!$R$5:$R$304,0.8)) | E13: =IF(COUNT('候选点'!$R$5:$R$304)<2,"",_xlfn.PERCENTILE.INC('候选点'!$R$5:$R$304,0.6)) | F13: =IF(COUNT('候选点'!$R$5:$R$304)<2,"",_xlfn.PERCENTILE.INC('候选点'!$R$5:$R$304,0.4)) | G13: =IF(COUNT('候选点'!$R$5:$R$304)<2,"",_xlfn.PERCENTILE.INC('候选点'!$R$5:$R$304,0.2)) | H13: 到车站距离
A14: A02 | B14: S | C14: 低=好 | D14: =IF(COUNT('候选点'!$S$5:$S$304)<2,"",_xlfn.PERCENTILE.INC('候选点'!$S$5:$S$304,0.8)) | E14: =IF(COUNT('候选点'!$S$5:$S$304)<2,"",_xlfn.PERCENTILE.INC('候选点'!$S$5:$S$304,0.6)) | F14: =IF(COUNT('候选点'!$S$5:$S$304)<2,"",_xlfn.PERCENTILE.INC('候选点'!$S$5:$S$304,0.4)) | G14: =IF(COUNT('候选点'!$S$5:$S$304)<2,"",_xlfn.PERCENTILE.INC('候选点'!$S$5:$S$304,0.2)) | H14: 到生活锚点距离
A15: A03 | B15: T | C15: 低=好 | D15: =IF(COUNT('候选点'!$T$5:$T$304)<2,"",_xlfn.PERCENTILE.INC('候选点'!$T$5:$T$304,0.8)) | E15: =IF(COUNT('候选点'!$T$5:$T$304)<2,"",_xlfn.PERCENTILE.INC('候选点'!$T$5:$T$304,0.6)) | F15: =IF(COUNT('候选点'!$T$5:$T$304)<2,"",_xlfn.PERCENTILE.INC('候选点'!$T$5:$T$304,0.4)) | G15: =IF(COUNT('候选点'!$T$5:$T$304)<2,"",_xlfn.PERCENTILE.INC('候选点'!$T$5:$T$304,0.2)) | H15: 到主干道距离
A16: K01 | B16: W | C16: 低=好 | D16: =IF(COUNT('候选点'!$W$5:$W$304)<2,"",_xlfn.PERCENTILE.INC('候选点'!$W$5:$W$304,0.8)) | E16: =IF(COUNT('候选点'!$W$5:$W$304)<2,"",_xlfn.PERCENTILE.INC('候选点'!$W$5:$W$304,0.6)) | F16: =IF(COUNT('候选点'!$W$5:$W$304)<2,"",_xlfn.PERCENTILE.INC('候选点'!$W$5:$W$304,0.4)) | G16: =IF(COUNT('候选点'!$W$5:$W$304)<2,"",_xlfn.PERCENTILE.INC('候选点'!$W$5:$W$304,0.2)) | H16: 坪租估计

Sheet 候选点
A1: 编号 | B1: 区域名称 | C1: 纬度 | D1: 经度 | E1: 600m内户数 | F1: 2km内户数 | G1: 600m内租赁户占比 | H1: 2km内租赁户占比 | I1: 600m内集合住宅占比 | J1: 600m内小户型占比 | K1: 2km内家庭户占比 | L1: 人口趋势指数 | M1: 600m内竞品数量 | N1: 2km内竞品数量 | O1: 最近竞品距离(米) | P1: 600m内强竞品(0/1) | Q1: 2km内强竞品(0/1) | R1: 到最近车站距离(米) | S1: 到生活锚点距离(米) | T1: 到主干道距离(米) | U1: 300m内停车锚点(0/1) | V1: 可视性评分(1-5) | W1: 坪租估计(円/坪) | X1: 阻隔评分(1-5) | Y1: 夜间风险评分(1-5) | Z1: 评分_D01 | AA1: 评分_D02 | AB1: 评分_D03 | AC1: 评分_D04 | AD1: 评分_D05 | AE1: 评分_D06 | AF1: 评分_D07 | AG1: 评分_D08 | AH1: 评分_C01 | AI1: 评分_C02 | AJ1: 评分_C03 | AK1: 评分_C04 | AL1: 评分_C05 | AM1: 评分_A01 | AN1: 评分_A02 | AO1: 评分_A03 | AP1: 评分_A04 | AQ1: 评分_A05 | AR1: 评分_K01 | AS1: 评分_R01 | AT1: 评分_R02 | AU1: 都市型一票否决 | AV1: 郊外型一票否决 | AW1: 都市型总分(0-100) | AX1: 郊外型总分(0-100)
A2: 权重_都市型 | Z2: =IFERROR(VLOOKUP(SUBSTITUTE(Z$1,"评分_",""),'指标字典'!$A$2:$K$22,10,FALSE),0) | AA2: =IFERROR(VLOOKUP(SUBSTITUTE(AA$1,"评分_",""),'指标字典'!$A$2:$K$22,10,FALSE),0) | AB2: =IFERROR(VLOOKUP(SUBSTITUTE(AB$1,"评分_",""),'指标字典'!$A$2:$K$22,10,FALSE),0) | AC2: =IFERROR(VLOOKUP(SUBSTITUTE(AC$1,"评分_",""),'指标字典'!$A$2:$K$22,10,FALSE),0) | AD2: =IFERROR(VLOOKUP(SUBSTITUTE(AD$1,"评分_",""),'指标字典'!$A$2:$K$22,10,FALSE),0) | AE2: =IFERROR(VLOOKUP(SUBSTITUTE(AE$1,"评分_",""),'指标字典'!$A$2:$K$22,10,FALSE),0) | AF2: =IFERROR(VLOOKUP(SUBSTITUTE(AF$1,"评分_",""),'指标字典'!$A$2:$K$22,10,FALSE),0) | AG2: =IFERROR(VLOOKUP(SUBSTITUTE(AG$1,"评分_",""),'指标字典'!$A$2:$K$22,10,FALSE),0) | ... AT2: =IFERROR(VLOOKUP(SUBSTITUTE(AT$1,"评分_",""),'指标字典'!$A$2:$K$22,10,FALSE),0)
A3: 权重_郊外型 | Z3: =IFERROR(VLOOKUP(SUBSTITUTE(Z$1,"评分_",""),'指标字典'!$A$2:$K$22,11,FALSE),0) | AA3: =IFERROR(VLOOKUP(SUBSTITUTE(AA$1,"评分_",""),'指标字典'!$A$2:$K$22,11,FALSE),0) | AB3: =IFERROR(VLOOKUP(SUBSTITUTE(AB$1,"评分_",""),'指标字典'!$A$2:$K$22,11,FALSE),0) | AC3: =IFERROR(VLOOKUP(SUBSTITUTE(AC$1,"评分_",""),'指标字典'!$A$2:$K$22,11,FALSE),0) | AD3: =IFERROR(VLOOKUP(SUBSTITUTE(AD$1,"评分_",""),'指标字典'!$A$2:$K$22,11,FALSE),0) | AE3: =IFERROR(VLOOKUP(SUBSTITUTE(AE$1,"评分_",""),'指标字典'!$A$2:$K$22,11,FALSE),0) | AF3: =IFERROR(VLOOKUP(SUBSTITUTE(AF$1,"评分_",""),'指标字典'!$A$2:$K$22,11,FALSE),0) | AG3: =IFERROR(VLOOKUP(SUBSTITUTE(AG$1,"评分_",""),'指标字典'!$A$2:$K$22,11,FALSE),0) | ... AT3: =IFERROR(VLOOKUP(SUBSTITUTE(AT$1,"评分_",""),'指标字典'!$A$2:$K$22,11,FALSE),0)
A4: 从第5行开始填数据（公式预置到第204行；需要更多行请向下填充）
A5: OSK001 | B5: 大阪府大阪市中央区高津一丁目 | C5: 34.667476 | D5: 135.51362 | E5: 18755 | F5: 122001 | G5: 0.705 | H5: 0.6446 | I5: 0.9457 | J5: 0.8515 | K5: 0.1914 | L5: 2.7 | M5: 5 | N5: 15 | O5: 128 | P5: 0 | Q5: 1 | R5: 134 | S5: 334 | T5: 159 | U5: 0 | V5: 4 | W5: 38760 | X5: 2 | Y5: 4 | Z5: =IF(E5="","",IF('分位数阈值'!$D$2="","",IFS(E5>='分位数阈值'!$D$2,5,E5>='分位数阈值'!$E$2,4,E5>='分位数阈值'!$F$2,3,E5>='分位数阈值'!$G$2,2,TRUE,1))) | AA5: =IF(F5="","",IF('分位数阈值'!$D$3="","",IFS(F5>='分位数阈值'!$D$3,5,F5>='分位数阈值'!$E$3,4,F5>='分位数阈值'!$F$3,3,F5>='分位数阈值'!$G$3,2,TRUE,1))) | AB5: =IF(G5="","",IF('分位数阈值'!$D$4="","",IFS(G5>='分位数阈值'!$D$4,5,G5>='分位数阈值'!$E$4,4,G5>='分位数阈值'!$F$4,3,G5>='分位数阈值'!$G$4,2,TRUE,1))) | AC5: =IF(H5="","",IF('分位数阈值'!$D$5="","",IFS(H5>='分位数阈值'!$D$5,5,H5>='分位数阈值'!$E$5,4,H5>='分位数阈值'!$F$5,3,H5>='分位数阈值'!$G$5,2,TRUE,1))) | AD5: =IF(I5="","",IF('分位数阈值'!$D$6="","",IFS(I5>='分位数阈值'!$D$6,5,I5>='分位数阈值'!$E$6,4,I5>='分位数阈值'!$F$6,3,I5>='分位数阈值'!$G$6,2,TRUE,1))) | AE5: =IF(J5="","",IF('分位数阈值'!$D$7="","",IFS(J5>='分位数阈值'!$D$7,5,J5>='分位数阈值'!$E$7,4,J5>='分位数阈值'!$F$7,3,J5>='分位数阈值'!$G$7,2,TRUE,1))) | AF5: =IF(K5="","",IF('分位数阈值'!$D$8="","",IFS(K5>='分位数阈值'!$D$8,5,K5>='分位数阈值'!$E$8,4,K5>='分位数阈值'!$F$8,3,K5>='分位数阈值'!$G$8,2,TRUE,1))) | AG5: =IF(L5="","",IF('分位数阈值'!$D$9="","",IFS(L5>='分位数阈值'!$D$9,5,L5>='分位数阈值'!$E$9,4,L5>='分位数阈值'!$F$9,3,L5>='分位数阈值'!$G$9,2,TRUE,1))) | AH5: =IF(M5="","",IF('分位数阈值'!$D$10="","",IFS(M5<='分位数阈值'!$G$10,5,M5<='分位数阈值'!$F$10,4,M5<='分位数阈值'!$E$10,3,M5<='分位数阈值'!$D$10,2,TRUE,1))) | AI5: =IF(N5="","",IF('分位数阈值'!$D$11="","",IFS(N5<='分位数阈值'!$G$11,5,N5<='分位数阈值'!$F$11,4,N5<='分位数阈值'!$E$11,3,N5<='分位数阈值'!$D$11,2,TRUE,1))) | AJ5: =IF(P5="","",IF(P5=1,1,5)) | AK5: =IF(Q5="","",IF(Q5=1,1,5)) | AL5: =IF(O5="","",IF('分位数阈值'!$D$12="","",IFS(O5>='分位数阈值'!$D$12,5,O5>='分位数阈值'!$E$12,4,O5>='分位数阈值'!$F$12,3,O5>='分位数阈值'!$G$12,2,TRUE,1))) | AM5: =IF(R5="","",IF('分位数阈值'!$D$13="","",IFS(R5<='分位数阈值'!$G$13,5,R5<='分位数阈值'!$F$13,4,R5<='分位数阈值'!$E$13,3,R5<='分位数阈值'!$D$13,2,TRUE,1))) | AN5: =IF(S5="","",IF('分位数阈值'!$D$14="","",IFS(S5<='分位数阈值'!$G$14,5,S5<='分位数阈值'!$F$14,4,S5<='分位数阈值'!$E$14,3,S5<='分位数阈值'!$D$14,2,TRUE,1))) | AO5: =IF(T5="","",IF('分位数阈值'!$D$15="","",IFS(T5<='分位数阈值'!$G$15,5,T5<='分位数阈值'!$F$15,4,T5<='分位数阈值'!$E$15,3,T5<='分位数阈值'!$D$15,2,TRUE,1))) | AP5: =IF(U5="","",IF(U5=1,5,1)) | AQ5: =IF(V5="","",V5) | AR5: =IF(W5="","",IF('分位数阈值'!$D$16="","",IFS(W5<='分位数阈值'!$G$16,5,W5<='分位数阈值'!$F$16,4,W5<='分位数阈值'!$E$16,3,W5<='分位数阈值'!$D$16,2,TRUE,1))) | AS5: =IF(X5="","",X5) | AT5: =IF(Y5="","",Y5) | AU5: =IF($A5="","",IF(OR(Z5=1,AR5=1,AJ5=1),"淘汰","通过")) | AV5: =IF($A5="","",IF(OR(AA5=1,AR5=1,AND(AK5=1,AI5=1),AO5=1),"淘汰","通过")) | AW5: =IF($A5="","",IF(AU5="淘汰","",ROUND(SUMPRODUCT(Z5:AT5,Z$2:AT$2)/5,1))) | AX5: =IF($A5="","",IF(AV5="淘汰","",ROUND(SUMPRODUCT(Z5:AT5,Z$3:AT$3)/5,1)))
A6: OSK002 | B6: 大阪府大阪市北区梅田三丁目 | C6: 34.700992 | D6: 135.49536 | E6: 14399 | F6: 196577 | G6: 0.7173 | H6: 0.6185 | I6: 0.8626 | J6: 0.8771 | K6: 0.1683 | L6: 4.36 | M6: 6 | N6: 23 | O6: 294 | P6: 0 | Q6: 1 | R6: 304 | S6: 324 | T6: 222 | U6: 0 | V6: 4 | W6: 25779 | X6: 3 | Y6: 3 | Z6: =IF(E6="","",IF('分位数阈值'!$D$2="","",IFS(E6>='分位数阈值'!$D$2,5,E6>='分位数阈值'!$E$2,4,E6>='分位数阈值'!$F$2,3,E6>='分位数阈值'!$G$2,2,TRUE,1))) | AA6: =IF(F6="","",IF('分位数阈值'!$D$3="","",IFS(F6>='分位数阈值'!$D$3,5,F6>='分位数阈值'!$E$3,4,F6>='分位数阈值'!$F$3,3,F6>='分位数阈值'!$G$3,2,TRUE,1))) | AB6: =IF(G6="","",IF('分位数阈值'!$D$4="","",IFS(G6>='分位数阈值'!$D$4,5,G6>='分位数阈值'!$E$4,4,G6>='分位数阈值'!$F$4,3,G6>='分位数阈值'!$G$4,2,TRUE,1))) | AC6: =IF(H6="","",IF('分位数阈值'!$D$5="","",IFS(H6>='分位数阈值'!$D$5,5,H6>='分位数阈值'!$E$5,4,H6>='分位数阈值'!$F$5,3,H6>='分位数阈值'!$G$5,2,TRUE,1))) | AD6: =IF(I6="","",IF('分位数阈值'!$D$6="","",IFS(I6>='分位数阈值'!$D$6,5,I6>='分位数阈值'!$E$6,4,I6>='分位数阈值'!$F$6,3,I6>='分位数阈值'!$G$6,2,TRUE,1))) | AE6: =IF(J6="","",IF('分位数阈值'!$D$7="","",IFS(J6>='分位数阈值'!$D$7,5,J6>='分位数阈值'!$E$7,4,J6>='分位数阈值'!$F$7,3,J6>='分位数阈值'!$G$7,2,TRUE,1))) | AF6: =IF(K6="","",IF('分位数阈值'!$D$8="","",IFS(K6>='分位数阈值'!$D$8,5,K6>='分位数阈值'!$E$8,4,K6>='分位数阈值'!$F$8,3,K6>='分位数阈值'!$G$8,2,TRUE,1))) | AG6: =IF(L6="","",IF('分位数阈值'!$D$9="","",IFS(L6>='分位数阈值'!$D$9,5,L6>='分位数阈值'!$E$9,4,L6>='分位数阈值'!$F$9,3,L6>='分位数阈值'!$G$9,2,TRUE,1))) | AH6: =IF(M6="","",IF('分位数阈值'!$D$10="","",IFS(M6<='分位数阈值'!$G$10,5,M6<='分位数阈值'!$F$10,4,M6<='分位数阈值'!$E$10,3,M6<='分位数阈值'!$D$10,2,TRUE,1))) | AI6: =IF(N6="","",IF('分位数阈值'!$D$11="","",IFS(N6<='分位数阈值'!$G$11,5,N6<='分位数阈值'!$F$11,4,N6<='分位数阈值'!$E$11,3,N6<='分位数阈值'!$D$11,2,TRUE,1))) | AJ6: =IF(P6="","",IF(P6=1,1,5)) | AK6: =IF(Q6="","",IF(Q6=1,1,5)) | AL6: =IF(O6="","",IF('分位数阈值'!$D$12="","",IFS(O6>='分位数阈值'!$D$12,5,O6>='分位数阈值'!$E$12,4,O6>='分位数阈值'!$F$12,3,O6>='分位数阈值'!$G$12,2,TRUE,1))) | AM6: =IF(R6="","",IF('分位数阈值'!$D$13="","",IFS(R6<='分位数阈值'!$G$13,5,R6<='分位数阈值'!$F$13,4,R6<='分位数阈值'!$E$13,3,R6<='分位数阈值'!$D$13,2,TRUE,1))) | AN6: =IF(S6="","",IF('分位数阈值'!$D$14="","",IFS(S6<='分位数阈值'!$G$14,5,S6<='分位数阈值'!$F$14,4,S6<='分位数阈值'!$E$14,3,S6<='分位数阈值'!$D$14,2,TRUE,1))) | AO6: =IF(T6="","",IF('分位数阈值'!$D$15="","",IFS(T6<='分位数阈值'!$G$15,5,T6<='分位数阈值'!$F$15,4,T6<='分位数阈值'!$E$15,3,T6<='分位数阈值'!$D$15,2,TRUE,1))) | AP6: =IF(U6="","",IF(U6=1,5,1)) | AQ6: =IF(V6="","",V6) | AR6: =IF(W6="","",IF('分位数阈值'!$D$16="","",IFS(W6<='分位数阈值'!$G$16,5,W6<='分位数阈值'!$F$16,4,W6<='分位数阈值'!$E$16,3,W6<='分位数阈值'!$D$16,2,TRUE,1))) | AS6: =IF(X6="","",X6) | AT6: =IF(Y6="","",Y6) | AU6: =IF($A6="","",IF(OR(Z6=1,AR6=1,AJ6=1),"淘汰","通过")) | AV6: =IF($A6="","",IF(OR(AA6=1,AR6=1,AND(AK6=1,AI6=1),AO6=1),"淘汰","通过")) | AW6: =IF($A6="","",IF(AU6="淘汰","",ROUND(SUMPRODUCT(Z6:AT6,Z$2:AT$2)/5,1))) | AX6: =IF($A6="","",IF(AV6="淘汰","",ROUND(SUMPRODUCT(Z6:AT6,Z$3:AT$3)/5,1)))
A7: OSK003 | B7: 大阪府大阪市西区阿波座一丁目 | C7: 34.674877 | D7: 135.48356 | E7: 13909 | F7: 142238 | G7: 0.7771 | H7: 0.673 | I7: 0.8981 | J7: 0.7814 | K7: 0.1414 | L7: 4.65 | M7: 6 | N7: 24 | O7: 118 | P7: 0 | Q7: 1 | R7: 182 | S7: 447 | T7: 178 | U7: 0 | V7: 4 | W7: 39328 | X7: 4 | Y7: 2 | Z7: =IF(E7="","",IF('分位数阈值'!$D$2="","",IFS(E7>='分位数阈值'!$D$2,5,E7>='分位数阈值'!$E$2,4,E7>='分位数阈值'!$F$2,3,E7>='分位数阈值'!$G$2,2,TRUE,1))) | AA7: =IF(F7="","",IF('分位数阈值'!$D$3="","",IFS(F7>='分位数阈值'!$D$3,5,F7>='分位数阈值'!$E$3,4,F7>='分位数阈值'!$F$3,3,F7>='分位数阈值'!$G$3,2,TRUE,1))) | AB7: =IF(G7="","",IF('分位数阈值'!$D$4="","",IFS(G7>='分位数阈值'!$D$4,5,G7>='分位数阈值'!$E$4,4,G7>='分位数阈值'!$F$4,3,G7>='分位数阈值'!$G$4,2,TRUE,1))) | AC7: =IF(H7="","",IF('分位数阈值'!$D$5="","",IFS(H7>='分位数阈值'!$D$5,5,H7>='分位数阈值'!$E$5,4,H7>='分位数阈值'!$F$5,3,H7>='分位数阈值'!$G$5,2,TRUE,1))) | AD7: =IF(I7="","",IF('分位数阈值'!$D$6="","",IFS(I7>='分位数阈值'!$D$6,5,I7>='分位数阈值'!$E$6,4,I7>='分位数阈值'!$F$6,3,I7>='分位数阈值'!$G$6,2,TRUE,1))) | AE7: =IF(J7="","",IF('分位数阈值'!$D$7="","",IFS(J7>='分位数阈值'!$D$7,5,J7>='分位数阈值'!$E$7,4,J7>='分位数阈值'!$F$7,3,J7>='分位数阈值'!$G$7,2,TRUE,1))) | AF7: =IF(K7="","",IF('分位数阈值'!$D$8="","",IFS(K7>='分位数阈值'!$D$8,5,K7>='分位数阈值'!$E$8,4,K7>='分位数阈值'!$F$8,3,K7>='分位数阈值'!$G$8,2,TRUE,1))) | AG7: =IF(L7="","",IF('分位数阈值'!$D$9="","",IFS(L7>='分位数阈值'!$D$9,5,L7>='分位数阈值'!$E$9,4,L7>='分位数阈值'!$F$9,3,L7>='分位数阈值'!$G$9,2,TRUE,1))) | AH7: =IF(M7="","",IF('分位数阈值'!$D$10="","",IFS(M7<='分位数阈值'!$G$10,5,M7<='分位数阈值'!$F$10,4,M7<='分位数阈值'!$E$10,3,M7<='分位数阈值'!$D$10,2,TRUE,1))) | AI7: =IF(N7="","",IF('分位数阈值'!$D$11="","",IFS(N7<='分位数阈值'!$G$11,5,N7<='分位数阈值'!$F$11,4,N7<='分位数阈值'!$E$11,3,N7<='分位数阈值'!$D$11,2,TRUE,1))) | AJ7: =IF(P7="","",IF(P7=1,1,5)) | AK7: =IF(Q7="","",IF(Q7=1,1,5)) | AL7: =IF(O7="","",IF('分位数阈值'!$D$12="","",IFS(O7>='分位数阈值'!$D$12,5,O7>='分位数阈值'!$E$12,4,O7>='分位数阈值'!$F$12,3,O7>='分位数阈值'!$G$12,2,TRUE,1))) | AM7: =IF(R7="","",IF('分位数阈值'!$D$13="","",IFS(R7<='分位数阈值'!$G$13,5,R7<='分位数阈值'!$F$13,4,R7<='分位数阈值'!$E$13,3,R7<='分位数阈值'!$D$13,2,TRUE,1))) | AN7: =IF(S7="","",IF('分位数阈值'!$D$14="","",IFS(S7<='分位数阈值'!$G$14,5,S7<='分位数阈值'!$F$14,4,S7<='分位数阈值'!$E$14,3,S7<='分位数阈值'!$D$14,2,TRUE,1))) | AO7: =IF(T7="","",IF('分位数阈值'!$D$15="","",IFS(T7<='分位数阈值'!$G$15,5,T7<='分位数阈值'!$F$15,4,T7<='分位数阈值'!$E$15,3,T7<='分位数阈值'!$D$15,2,TRUE,1))) | AP7: =IF(U7="","",IF(U7=1,5,1)) | AQ7: =IF(V7="","",V7) | AR7: =IF(W7="","",IF('分位数阈值'!$D$16="","",IFS(W7<='分位数阈值'!$G$16,5,W7<='分位数阈值'!$F$16,4,W7<='分位数阈值'!$E$16,3,W7<='分位数阈值'!$D$16,2,TRUE,1))) | AS7: =IF(X7="","",X7) | AT7: =IF(Y7="","",Y7) | AU7: =IF($A7="","",IF(OR(Z7=1,AR7=1,AJ7=1),"淘汰","通过")) | AV7: =IF($A7="","",IF(OR(AA7=1,AR7=1,AND(AK7=1,AI7=1),AO7=1),"淘汰","通过")) | AW7: =IF($A7="","",IF(AU7="淘汰","",ROUND(SUMPRODUCT(Z7:AT7,Z$2:AT$2)/5,1))) | AX7: =IF($A7="","",IF(AV7="淘汰","",ROUND(SUMPRODUCT(Z7:AT7,Z$3:AT$3)/5,1)))
A8: OSK004 | B8: 大阪府大阪市天王寺区上本町六丁目 | C8: 34.664063 | D8: 135.52031 | E8: 15410 | F8: 136879 | G8: 0.8386 | H8: 0.7753 | I8: 0.8909 | J8: 0.8483 | K8: 0.1517 | L8: 4.6 | M8: 5 | N8: 19 | O8: 134 | P8: 0 | Q8: 1 | R8: 238 | S8: 416 | T8: 130 | U8: 0 | V8: 5 | W8: 33662 | X8: 2 | Y8: 2 | Z8: =IF(E8="","",IF('分位数阈值'!$D$2="","",IFS(E8>='分位数阈值'!$D$2,5,E8>='分位数阈值'!$E$2,4,E8>='分位数阈值'!$F$2,3,E8>='分位数阈值'!$G$2,2,TRUE,1))) | AA8: =IF(F8="","",IF('分位数阈值'!$D$3="","",IFS(F8>='分位数阈值'!$D$3,5,F8>='分位数阈值'!$E$3,4,F8>='分位数阈值'!$F$3,3,F8>='分位数阈值'!$G$3,2,TRUE,1))) | AB8: =IF(G8="","",IF('分位数阈值'!$D$4="","",IFS(G8>='分位数阈值'!$D$4,5,G8>='分位数阈值'!$E$4,4,G8>='分位数阈值'!$F$4,3,G8>='分位数阈值'!$G$4,2,TRUE,1))) | AC8: =IF(H8="","",IF('分位数阈值'!$D$5="","",IFS(H8>='分位数阈值'!$D$5,5,H8>='分位数阈值'!$E$5,4,H8>='分位数阈值'!$F$5,3,H8>='分位数阈值'!$G$5,2,TRUE,1))) | AD8: =IF(I8="","",IF('分位数阈值'!$D$6="","",IFS(I8>='分位数阈值'!$D$6,5,I8>='分位数阈值'!$E$6,4,I8>='分位数阈值'!$F$6,3,I8>='分位数阈值'!$G$6,2,TRUE,1))) | AE8: =IF(J8="","",IF('分位数阈值'!$D$7="","",IFS(J8>='分位数阈值'!$D$7,5,J8>='分位数阈值'!$E$7,4,J8>='分位数阈值'!$F$7,3,J8>='分位数阈值'!$G$7,2,TRUE,1))) | AF8: =IF(K8="","",IF('分位数阈值'!$D$8="","",IFS(K8>='分位数阈值'!$D$8,5,K8>='分位数阈值'!$E$8,4,K8>='分位数阈值'!$F$8,3,K8>='分位数阈值'!$G$8,2,TRUE,1))) | AG8: =IF(L8="","",IF('分位数阈值'!$D$9="","",IFS(L8>='分位数阈值'!$D$9,5,L8>='分位数阈值'!$E$9,4,L8>='分位数阈值'!$F$9,3,L8>='分位数阈值'!$G$9,2,TRUE,1))) | AH8: =IF(M8="","",IF('分位数阈值'!$D$10="","",IFS(M8<='分位数阈值'!$G$10,5,M8<='分位数阈值'!$F$10,4,M8<='分位数阈值'!$E$10,3,M8<='分位数阈值'!$D$10,2,TRUE,1))) | AI8: =IF(N8="","",IF('分位数阈值'!$D$11="","",IFS(N8<='分位数阈值'!$G$11,5,N8<='分位数阈值'!$F$11,4,N8<='分位数阈值'!$E$11,3,N8<='分位数阈值'!$D$11,2,TRUE,1))) | AJ8: =IF(P8="","",IF(P8=1,1,5)) | AK8: =IF(Q8="","",IF(Q8=1,1,5)) | AL8: =IF(O8="","",IF('分位数阈值'!$D$12="","",IFS(O8>='分位数阈值'!$D$12,5,O8>='分位数阈值'!$E$12,4,O8>='分位数阈值'!$F$12,3,O8>='分位数阈值'!$G$12,2,TRUE,1))) | AM8: =IF(R8="","",IF('分位数阈值'!$D$13="","",IFS(R8<='分位数阈值'!$G$13,5,R8<='分位数阈值'!$F$13,4,R8<='分位数阈值'!$E$13,3,R8<='分位数阈值'!$D$13,2,TRUE,1))) | AN8: =IF(S8="","",IF('分位数阈值'!$D$14="","",IFS(S8<='分位数阈值'!$G$14,5,S8<='分位数阈值'!$F$14,4,S8<='分位数阈值'!$E$14,3,S8<='分位数阈值'!$D$14,2,TRUE,1))) | AO8: =IF(T8="","",IF('分位数阈值'!$D$15="","",IFS(T8<='分位数阈值'!$G$15,5,T8<='分位数阈值'!$F$15,4,T8<='分位数阈值'!$E$15,3,T8<='分位数阈值'!$D$15,2,TRUE,1))) | AP8: =IF(U8="","",IF(U8=1,5,1)) | AQ8: =IF(V8="","",V8) | AR8: =IF(W8="","",IF('分位数阈值'!$D$16="","",IFS(W8<='分位数阈值'!$G$16,5,W8<='分位数阈值'!$F$16,4,W8<='分位数阈值'!$E$16,3,W8<='分位数阈值'!$D$16,2,TRUE,1))) | AS8: =IF(X8="","",X8) | AT8: =IF(Y8="","",Y8) | AU8: =IF($A8="","",IF(OR(Z8=1,AR8=1,AJ8=1),"淘汰","通过")) | AV8: =IF($A8="","",IF(OR(AA8=1,AR8=1,AND(AK8=1,AI8=1),AO8=1),"淘汰","通过")) | AW8: =IF($A8="","",IF(AU8="淘汰","",ROUND(SUMPRODUCT(Z8:AT8,Z$2:AT$2)/5,1))) | AX8: =IF($A8="","",IF(AV8="淘汰","",ROUND(SUMPRODUCT(Z8:AT8,Z$3:AT$3)/5,1)))
A9: OSK005 | B9: 大阪府大阪市浪速区難波中二丁目 | C9: 34.665229 | D9: 135.50299 | E9: 20129 | F9: 153773 | G9: 0.6627 | H9: 0.6763 | I9: 0.9795 | J9: 0.8294 | K9: 0.1977 | L9: 4.48 | M9: 3 | N9: 26 | O9: 230 | P9: 0 | Q9: 1 | R9: 253 | S9: 157 | T9: 137 | U9: 0 | V9: 5 | W9: 39889 | X9: 3 | Y9: 3 | Z9: =IF(E9="","",IF('分位数阈值'!$D$2="","",IFS(E9>='分位数阈值'!$D$2,5,E9>='分位数阈值'!$E$2,4,E9>='分位数阈值'!$F$2,3,E9>='分位数阈值'!$G$2,2,TRUE,1))) | AA9: =IF(F9="","",IF('分位数阈值'!$D$3="","",IFS(F9>='分位数阈值'!$D$3,5,F9>='分位数阈值'!$E$3,4,F9>='分位数阈值'!$F$3,3,F9>='分位数阈值'!$G$3,2,TRUE,1))) | AB9: =IF(G9="","",IF('分位数阈值'!$D$4="","",IFS(G9>='分位数阈值'!$D$4,5,G9>='分位数阈值'!$E$4,4,G9>='分位数阈值'!$F$4,3,G9>='分位数阈值'!$G$4,2,TRUE,1))) | AC9: =IF(H9="","",IF('分位数阈值'!$D$5="","",IFS(H9>='分位数阈值'!$D$5,5,H9>='分位数阈值'!$E$5,4,H9>='分位数阈值'!$F$5,3,H9>='分位数阈值'!$G$5,2,TRUE,1))) | AD9: =IF(I9="","",IF('分位数阈值'!$D$6="","",IFS(I9>='分位数阈值'!$D$6,5,I9>='分位数阈值'!$E$6,4,I9>='分位数阈值'!$F$6,3,I9>='分位数阈值'!$G$6,2,TRUE,1))) | AE9: =IF(J9="","",IF('分位数阈值'!$D$7="","",IFS(J9>='分位数阈值'!$D$7,5,J9>='分位数阈值'!$E$7,4,J9>='分位数阈值'!$F$7,3,J9>='分位数阈值'!$G$7,2,TRUE,1))) | AF9: =IF(K9="","",IF('分位数阈值'!$D$8="","",IFS(K9>='分位数阈值'!$D$8,5,K9>='分位数阈值'!$E$8,4,K9>='分位数阈值'!$F$8,3,K9>='分位数阈值'!$G$8,2,TRUE,1))) | AG9: =IF(L9="","",IF('分位数阈值'!$D$9="","",IFS(L9>='分位数阈值'!$D$9,5,L9>='分位数阈值'!$E$9,4,L9>='分位数阈值'!$F$9,3,L9>='分位数阈值'!$G$9,2,TRUE,1))) | AH9: =IF(M9="","",IF('分位数阈值'!$D$10="","",IFS(M9<='分位数阈值'!$G$10,5,M9<='分位数阈值'!$F$10,4,M9<='分位数阈值'!$E$10,3,M9<='分位数阈值'!$D$10,2,TRUE,1))) | AI9: =IF(N9="","",IF('分位数阈值'!$D$11="","",IFS(N9<='分位数阈值'!$G$11,5,N9<='分位数阈值'!$F$11,4,N9<='分位数阈值'!$E$11,3,N9<='分位数阈值'!$D$11,2,TRUE,1))) | AJ9: =IF(P9="","",IF(P9=1,1,5)) | AK9: =IF(Q9="","",IF(Q9=1,1,5)) | AL9: =IF(O9="","",IF('分位数阈值'!$D$12="","",IFS(O9>='分位数阈值'!$D$12,5,O9>='分位数阈值'!$E$12,4,O9>='分位数阈值'!$F$12,3,O9>='分位数阈值'!$G$12,2,TRUE,1))) | AM9: =IF(R9="","",IF('分位数阈值'!$D$13="","",IFS(R9<='分位数阈值'!$G$13,5,R9<='分位数阈值'!$F$13,4,R9<='分位数阈值'!$E$13,3,R9<='分位数阈值'!$D$13,2,TRUE,1))) | AN9: =IF(S9="","",IF('分位数阈值'!$D$14="","",IFS(S9<='分位数阈值'!$G$14,5,S9<='分位数阈值'!$F$14,4,S9<='分位数阈值'!$E$14,3,S9<='分位数阈值'!$D$14,2,TRUE,1))) | AO9: =IF(T9="","",IF('分位数阈值'!$D$15="","",IFS(T9<='分位数阈值'!$G$15,5,T9<='分位数阈值'!$F$15,4,T9<='分位数阈值'!$E$15,3,T9<='分位数阈值'!$D$15,2,TRUE,1))) | AP9: =IF(U9="","",IF(U9=1,5,1)) | AQ9: =IF(V9="","",V9) | AR9: =IF(W9="","",IF('分位数阈值'!$D$16="","",IFS(W9<='分位数阈值'!$G$16,5,W9<='分位数阈值'!$F$16,4,W9<='分位数阈值'!$E$16,3,W9<='分位数阈值'!$D$16,2,TRUE,1))) | AS9: =IF(X9="","",X9) | AT9: =IF(Y9="","",Y9) | AU9: =IF($A9="","",IF(OR(Z9=1,AR9=1,AJ9=1),"淘汰","通过")) | AV9: =IF($A9="","",IF(OR(AA9=1,AR9=1,AND(AK9=1,AI9=1),AO9=1),"淘汰","通过")) | AW9: =IF($A9="","",IF(AU9="淘汰","",ROUND(SUMPRODUCT(Z9:AT9,Z$2:AT$2)/5,1))) | AX9: =IF($A9="","",IF(AV9="淘汰","",ROUND(SUMPRODUCT(Z9:AT9,Z$3:AT$3)/5,1)))
A10: OSK006 | B10: 大阪府大阪市福島区福島五丁目 | C10: 34.695966 | D10: 135.48663 | E10: 20835 | F10: 143876 | G10: 0.7778 | H10: 0.7218 | I10: 0.8699 | J10: 0.8644 | K10: 0.1632 | L10: 4.29 | M10: 5 | N10: 15 | O10: 151 | P10: 1 | Q10: 0 | R10: 317 | S10: 394 | T10: 112 | U10: 1 | V10: 5 | W10: 41098 | X10: 2 | Y10: 3 | Z10: =IF(E10="","",IF('分位数阈值'!$D$2="","",IFS(E10>='分位数阈值'!$D$2,5,E10>='分位数阈值'!$E$2,4,E10>='分位数阈值'!$F$2,3,E10>='分位数阈值'!$G$2,2,TRUE,1))) | AA10: =IF(F10="","",IF('分位数阈值'!$D$3="","",IFS(F10>='分位数阈值'!$D$3,5,F10>='分位数阈值'!$E$3,4,F10>='分位数阈值'!$F$3,3,F10>='分位数阈值'!$G$3,2,TRUE,1))) | AB10: =IF(G10="","",IF('分位数阈值'!$D$4="","",IFS(G10>='分位数阈值'!$D$4,5,G10>='分位数阈值'!$E$4,4,G10>='分位数阈值'!$F$4,3,G10>='分位数阈值'!$G$4,2,TRUE,1))) | AC10: =IF(H10="","",IF('分位数阈值'!$D$5="","",IFS(H10>='分位数阈值'!$D$5,5,H10>='分位数阈值'!$E$5,4,H10>='分位数阈值'!$F$5,3,H10>='分位数阈值'!$G$5,2,TRUE,1))) | AD10: =IF(I10="","",IF('分位数阈值'!$D$6="","",IFS(I10>='分位数阈值'!$D$6,5,I10>='分位数阈值'!$E$6,4,I10>='分位数阈值'!$F$6,3,I10>='分位数阈值'!$G$6,2,TRUE,1))) | AE10: =IF(J10="","",IF('分位数阈值'!$D$7="","",IFS(J10>='分位数阈值'!$D$7,5,J10>='分位数阈值'!$E$7,4,J10>='分位数阈值'!$F$7,3,J10>='分位数阈值'!$G$7,2,TRUE,1))) | AF10: =IF(K10="","",IF('分位数阈值'!$D$8="","",IFS(K10>='分位数阈值'!$D$8,5,K10>='分位数阈值'!$E$8,4,K10>='分位数阈值'!$F$8,3,K10>='分位数阈值'!$G$8,2,TRUE,1))) | AG10: =IF(L10="","",IF('分位数阈值'!$D$9="","",IFS(L10>='分位数阈值'!$D$9,5,L10>='分位数阈值'!$E$9,4,L10>='分位数阈值'!$F$9,3,L10>='分位数阈值'!$G$9,2,TRUE,1))) | AH10: =IF(M10="","",IF('分位数阈值'!$D$10="","",IFS(M10<='分位数阈值'!$G$10,5,M10<='分位数阈值'!$F$10,4,M10<='分位数阈值'!$E$10,3,M10<='分位数阈值'!$D$10,2,TRUE,1))) | AI10: =IF(N10="","",IF('分位数阈值'!$D$11="","",IFS(N10<='分位数阈值'!$G$11,5,N10<='分位数阈值'!$F$11,4,N10<='分位数阈值'!$E$11,3,N10<='分位数阈值'!$D$11,2,TRUE,1))) | AJ10: =IF(P10="","",IF(P10=1,1,5)) | AK10: =IF(Q10="","",IF(Q10=1,1,5)) | AL10: =IF(O10="","",IF('分位数阈值'!$D$12="","",IFS(O10>='分位数阈值'!$D$12,5,O10>='分位数阈值'!$E$12,4,O10>='分位数阈值'!$F$12,3,O10>='分位数阈值'!$G$12,2,TRUE,1))) | AM10: =IF(R10="","",IF('分位数阈值'!$D$13="","",IFS(R10<='分位数阈值'!$G$13,5,R10<='分位数阈值'!$F$13,4,R10<='分位数阈值'!$E$13,3,R10<='分位数阈值'!$D$13,2,TRUE,1))) | AN10: =IF(S10="","",IF('分位数阈值'!$D$14="","",IFS(S10<='分位数阈值'!$G$14,5,S10<='分位数阈值'!$F$14,4,S10<='分位数阈值'!$E$14,3,S10<='分位数阈值'!$D$14,2,TRUE,1))) | AO10: =IF(T10="","",IF('分位数阈值'!$D$15="","",IFS(T10<='分位数阈值'!$G$15,5,T10<='分位数阈值'!$F$15,4,T10<='分位数阈值'!$E$15,3,T10<='分位数阈值'!$D$15,2,TRUE,1))) | AP10: =IF(U10="","",IF(U10=1,5,1)) | AQ10: =IF(V10="","",V10) | AR10: =IF(W10="","",IF('分位数阈值'!$D$16="","",IFS(W10<='分位数阈值'!$G$16,5,W10<='分位数阈值'!$F$16,4,W10<='分位数阈值'!$E$16,3,W10<='分位数阈值'!$D$16,2,TRUE,1))) | AS10: =IF(X10="","",X10) | AT10: =IF(Y10="","",Y10) | AU10: =IF($A10="","",IF(OR(Z10=1,AR10=1,AJ10=1),"淘汰","通过")) | AV10: =IF($A10="","",IF(OR(AA10=1,AR10=1,AND(AK10=1,AI10=1),AO10=1),"淘汰","通过")) | AW10: =IF($A10="","",IF(AU10="淘汰","",ROUND(SUMPRODUCT(Z10:AT10,Z$2:AT$2)/5,1))) | AX10: =IF($A10="","",IF(AV10="淘汰","",ROUND(SUMPRODUCT(Z10:AT10,Z$3:AT$3)/5,1)))
A11: OSK007 | B11: 大阪府大阪市都島区都島本通三丁目 | C11: 34.706329 | D11: 135.52197 | E11: 14361 | F11: 98987 | G11: 0.6593 | H11: 0.621 | I11: 0.761 | J11: 0.8332 | K11: 0.1923 | L11: 2.53 | M11: 3 | N11: 19 | O11: 186 | P11: 0 | Q11: 0 | R11: 475 | S11: 347 | T11: 220 | U11: 1 | V11: 3 | W11: 20733 | X11: 4 | Y11: 3 | Z11: =IF(E11="","",IF('分位数阈值'!$D$2="","",IFS(E11>='分位数阈值'!$D$2,5,E11>='分位数阈值'!$E$2,4,E11>='分位数阈值'!$F$2,3,E11>='分位数阈值'!$G$2,2,TRUE,1))) | AA11: =IF(F11="","",IF('分位数阈值'!$D$3="","",IFS(F11>='分位数阈值'!$D$3,5,F11>='分位数阈值'!$E$3,4,F11>='分位数阈值'!$F$3,3,F11>='分位数阈值'!$G$3,2,TRUE,1))) | AB11: =IF(G11="","",IF('分位数阈值'!$D$4="","",IFS(G11>='分位数阈值'!$D$4,5,G11>='分位数阈值'!$E$4,4,G11>='分位数阈值'!$F$4,3,G11>='分位数阈值'!$G$4,2,TRUE,1))) | AC11: =IF(H11="","",IF('分位数阈值'!$D$5="","",IFS(H11>='分位数阈值'!$D$5,5,H11>='分位数阈值'!$E$5,4,H11>='分位数阈值'!$F$5,3,H11>='分位数阈值'!$G$5,2,TRUE,1))) | AD11: =IF(I11="","",IF('分位数阈值'!$D$6="","",IFS(I11>='分位数阈值'!$D$6,5,I11>='分位数阈值'!$E$6,4,I11>='分位数阈值'!$F$6,3,I11>='分位数阈值'!$G$6,2,TRUE,1))) | AE11: =IF(J11="","",IF('分位数阈值'!$D$7="","",IFS(J11>='分位数阈值'!$D$7,5,J11>='分位数阈值'!$E$7,4,J11>='分位数阈值'!$F$7,3,J11>='分位数阈值'!$G$7,2,TRUE,1))) | AF11: =IF(K11="","",IF('分位数阈值'!$D$8="","",IFS(K11>='分位数阈值'!$D$8,5,K11>='分位数阈值'!$E$8,4,K11>='分位数阈值'!$F$8,3,K11>='分位数阈值'!$G$8,2,TRUE,1))) | AG11: =IF(L11="","",IF('分位数阈值'!$D$9="","",IFS(L11>='分位数阈值'!$D$9,5,L11>='分位数阈值'!$E$9,4,L11>='分位数阈值'!$F$9,3,L11>='分位数阈值'!$G$9,2,TRUE,1))) | AH11: =IF(M11="","",IF('分位数阈值'!$D$10="","",IFS(M11<='分位数阈值'!$G$10,5,M11<='分位数阈值'!$F$10,4,M11<='分位数阈值'!$E$10,3,M11<='分位数阈值'!$D$10,2,TRUE,1))) | AI11: =IF(N11="","",IF('分位数阈值'!$D$11="","",IFS(N11<='分位数阈值'!$G$11,5,N11<='分位数阈值'!$F$11,4,N11<='分位数阈值'!$E$11,3,N11<='分位数阈值'!$D$11,2,TRUE,1))) | AJ11: =IF(P11="","",IF(P11=1,1,5)) | AK11: =IF(Q11="","",IF(Q11=1,1,5)) | AL11: =IF(O11="","",IF('分位数阈值'!$D$12="","",IFS(O11>='分位数阈值'!$D$12,5,O11>='分位数阈值'!$E$12,4,O11>='分位数阈值'!$F$12,3,O11>='分位数阈值'!$G$12,2,TRUE,1))) | AM11: =IF(R11="","",IF('分位数阈值'!$D$13="","",IFS(R11<='分位数阈值'!$G$13,5,R11<='分位数阈值'!$F$13,4,R11<='分位数阈值'!$E$13,3,R11<='分位数阈值'!$D$13,2,TRUE,1))) | AN11: =IF(S11="","",IF('分位数阈值'!$D$14="","",IFS(S11<='分位数阈值'!$G$14,5,S11<='分位数阈值'!$F$14,4,S11<='分位数阈值'!$E$14,3,S11<='分位数阈值'!$D$14,2,TRUE,1))) | AO11: =IF(T11="","",IF('分位数阈值'!$D$15="","",IFS(T11<='分位数阈值'!$G$15,5,T11<='分位数阈值'!$F$15,4,T11<='分位数阈值'!$E$15,3,T11<='分位数阈值'!$D$15,2,TRUE,1))) | AP11: =IF(U11="","",IF(U11=1,5,1)) | AQ11: =IF(V11="","",V11) | AR11: =IF(W11="","",IF('分位数阈值'!$D$16="","",IFS(W11<='分位数阈值'!$G$16,5,W11<='分位数阈值'!$F$16,4,W11<='分位数阈值'!$E$16,3,W11<='分位数阈值'!$D$16,2,TRUE,1))) | AS11: =IF(X11="","",X11) | AT11: =IF(Y11="","",Y11) | AU11: =IF($A11="","",IF(OR(Z11=1,AR11=1,AJ11=1),"淘汰","通过")) | AV11: =IF($A11="","",IF(OR(AA11=1,AR11=1,AND(AK11=1,AI11=1),AO11=1),"淘汰","通过")) | AW11: =IF($A11="","",IF(AU11="淘汰","",ROUND(SUMPRODUCT(Z11:AT11,Z$2:AT$2)/5,1))) | AX11: =IF($A11="","",IF(AV11="淘汰","",ROUND(SUMPRODUCT(Z11:AT11,Z$3:AT$3)/5,1)))
A12: OSK008 | B12: 大阪府大阪市城東区蒲生四丁目 | C12: 34.693162 | D12: 135.54504 | E12: 13418 | F12: 106026 | G12: 0.7582 | H12: 0.6891 | I12: 0.7163 | J12: 0.7 | K12: 0.2169 | L12: 2.54 | M12: 2 | N12: 21 | O12: 308 | P12: 0 | Q12: 0 | R12: 554 | S12: 236 | T12: 106 | U12: 0 | V12: 4 | W12: 22538 | X12: 4 | Y12: 4 | Z12: =IF(E12="","",IF('分位数阈值'!$D$2="","",IFS(E12>='分位数阈值'!$D$2,5,E12>='分位数阈值'!$E$2,4,E12>='分位数阈值'!$F$2,3,E12>='分位数阈值'!$G$2,2,TRUE,1))) | AA12: =IF(F12="","",IF('分位数阈值'!$D$3="","",IFS(F12>='分位数阈值'!$D$3,5,F12>='分位数阈值'!$E$3,4,F12>='分位数阈值'!$F$3,3,F12>='分位数阈值'!$G$3,2,TRUE,1))) | AB12: =IF(G12="","",IF('分位数阈值'!$D$4="","",IFS(G12>='分位数阈值'!$D$4,5,G12>='分位数阈值'!$E$4,4,G12>='分位数阈值'!$F$4,3,G12>='分位数阈值'!$G$4,2,TRUE,1))) | AC12: =IF(H12="","",IF('分位数阈值'!$D$5="","",IFS(H12>='分位数阈值'!$D$5,5,H12>='分位数阈值'!$E$5,4,H12>='分位数阈值'!$F$5,3,H12>='分位数阈值'!$G$5,2,TRUE,1))) | AD12: =IF(I12="","",IF('分位数阈值'!$D$6="","",IFS(I12>='分位数阈值'!$D$6,5,I12>='分位数阈值'!$E$6,4,I12>='分位数阈值'!$F$6,3,I12>='分位数阈值'!$G$6,2,TRUE,1))) | AE12: =IF(J12="","",IF('分位数阈值'!$D$7="","",IFS(J12>='分位数阈值'!$D$7,5,J12>='分位数阈值'!$E$7,4,J12>='分位数阈值'!$F$7,3,J12>='分位数阈值'!$G$7,2,TRUE,1))) | AF12: =IF(K12="","",IF('分位数阈值'!$D$8="","",IFS(K12>='分位数阈值'!$D$8,5,K12>='分位数阈值'!$E$8,4,K12>='分位数阈值'!$F$8,3,K12>='分位数阈值'!$G$8,2,TRUE,1))) | AG12: =IF(L12="","",IF('分位数阈值'!$D$9="","",IFS(L12>='分位数阈值'!$D$9,5,L12>='分位数阈值'!$E$9,4,L12>='分位数阈值'!$F$9,3,L12>='分位数阈值'!$G$9,2,TRUE,1))) | AH12: =IF(M12="","",IF('分位数阈值'!$D$10="","",IFS(M12<='分位数阈值'!$G$10,5,M12<='分位数阈值'!$F$10,4,M12<='分位数阈值'!$E$10,3,M12<='分位数阈值'!$D$10,2,TRUE,1))) | AI12: =IF(N12="","",IF('分位数阈值'!$D$11="","",IFS(N12<='分位数阈值'!$G$11,5,N12<='分位数阈值'!$F$11,4,N12<='分位数阈值'!$E$11,3,N12<='分位数阈值'!$D$11,2,TRUE,1))) | AJ12: =IF(P12="","",IF(P12=1,1,5)) | AK12: =IF(Q12="","",IF(Q12=1,1,5)) | AL12: =IF(O12="","",IF('分位数阈值'!$D$12="","",IFS(O12>='分位数阈值'!$D$12,5,O12>='分位数阈值'!$E$12,4,O12>='分位数阈值'!$F$12,3,O12>='分位数阈值'!$G$12,2,TRUE,1))) | AM12: =IF(R12="","",IF('分位数阈值'!$D$13="","",IFS(R12<='分位数阈值'!$G$13,5,R12<='分位数阈值'!$F$13,4,R12<='分位数阈值'!$E$13,3,R12<='分位数阈值'!$D$13,2,TRUE,1))) | AN12: =IF(S12="","",IF('分位数阈值'!$D$14="","",IFS(S12<='分位数阈值'!$G$14,5,S12<='分位数阈值'!$F$14,4,S12<='分位数阈值'!$E$14,3,S12<='分位数阈值'!$D$14,2,TRUE,1))) | AO12: =IF(T12="","",IF('分位数阈值'!$D$15="","",IFS(T12<='分位数阈值'!$G$15,5,T12<='分位数阈值'!$F$15,4,T12<='分位数阈值'!$E$15,3,T12<='分位数阈值'!$D$15,2,TRUE,1))) | AP12: =IF(U12="","",IF(U12=1,5,1)) | AQ12: =IF(V12="","",V12) | AR12: =IF(W12="","",IF('分位数阈值'!$D$16="","",IFS(W12<='分位数阈值'!$G$16,5,W12<='分位数阈值'!$F$16,4,W12<='分位数阈值'!$E$16,3,W12<='分位数阈值'!$D$16,2,TRUE,1))) | AS12: =IF(X12="","",X12) | AT12: =IF(Y12="","",Y12) | AU12: =IF($A12="","",IF(OR(Z12=1,AR12=1,AJ12=1),"淘汰","通过")) | AV12: =IF($A12="","",IF(OR(AA12=1,AR12=1,AND(AK12=1,AI12=1),AO12=1),"淘汰","通过")) | AW12: =IF($A12="","",IF(AU12="淘汰","",ROUND(SUMPRODUCT(Z12:AT12,Z$2:AT$2)/5,1))) | AX12: =IF($A12="","",IF(AV12="淘汰","",ROUND(SUMPRODUCT(Z12:AT12,Z$3:AT$3)/5,1)))
A13: OSK009 | B13: 大阪府大阪市東成区大今里西二丁目 | C13: 34.670313 | D13: 135.54776 | E13: 11818 | F13: 113751 | G13: 0.7482 | H13: 0.5547 | I13: 0.7437 | J13: 0.7442 | K13: 0.1922 | L13: 2.7 | M13: 2 | N13: 21 | O13: 266 | P13: 0 | Q13: 0 | R13: 175 | S13: 600 | T13: 306 | U13: 0 | V13: 5 | W13: 27882 | X13: 3 | Y13: 4 | Z13: =IF(E13="","",IF('分位数阈值'!$D$2="","",IFS(E13>='分位数阈值'!$D$2,5,E13>='分位数阈值'!$E$2,4,E13>='分位数阈值'!$F$2,3,E13>='分位数阈值'!$G$2,2,TRUE,1))) | AA13: =IF(F13="","",IF('分位数阈值'!$D$3="","",IFS(F13>='分位数阈值'!$D$3,5,F13>='分位数阈值'!$E$3,4,F13>='分位数阈值'!$F$3,3,F13>='分位数阈值'!$G$3,2,TRUE,1))) | AB13: =IF(G13="","",IF('分位数阈值'!$D$4="","",IFS(G13>='分位数阈值'!$D$4,5,G13>='分位数阈值'!$E$4,4,G13>='分位数阈值'!$F$4,3,G13>='分位数阈值'!$G$4,2,TRUE,1))) | AC13: =IF(H13="","",IF('分位数阈值'!$D$5="","",IFS(H13>='分位数阈值'!$D$5,5,H13>='分位数阈值'!$E$5,4,H13>='分位数阈值'!$F$5,3,H13>='分位数阈值'!$G$5,2,TRUE,1))) | AD13: =IF(I13="","",IF('分位数阈值'!$D$6="","",IFS(I13>='分位数阈值'!$D$6,5,I13>='分位数阈值'!$E$6,4,I13>='分位数阈值'!$F$6,3,I13>='分位数阈值'!$G$6,2,TRUE,1))) | AE13: =IF(J13="","",IF('分位数阈值'!$D$7="","",IFS(J13>='分位数阈值'!$D$7,5,J13>='分位数阈值'!$E$7,4,J13>='分位数阈值'!$F$7,3,J13>='分位数阈值'!$G$7,2,TRUE,1))) | AF13: =IF(K13="","",IF('分位数阈值'!$D$8="","",IFS(K13>='分位数阈值'!$D$8,5,K13>='分位数阈值'!$E$8,4,K13>='分位数阈值'!$F$8,3,K13>='分位数阈值'!$G$8,2,TRUE,1))) | AG13: =IF(L13="","",IF('分位数阈值'!$D$9="","",IFS(L13>='分位数阈值'!$D$9,5,L13>='分位数阈值'!$E$9,4,L13>='分位数阈值'!$F$9,3,L13>='分位数阈值'!$G$9,2,TRUE,1))) | AH13: =IF(M13="","",IF('分位数阈值'!$D$10="","",IFS(M13<='分位数阈值'!$G$10,5,M13<='分位数阈值'!$F$10,4,M13<='分位数阈值'!$E$10,3,M13<='分位数阈值'!$D$10,2,TRUE,1))) | AI13: =IF(N13="","",IF('分位数阈值'!$D$11="","",IFS(N13<='分位数阈值'!$G$11,5,N13<='分位数阈值'!$F$11,4,N13<='分位数阈值'!$E$11,3,N13<='分位数阈值'!$D$11,2,TRUE,1))) | AJ13: =IF(P13="","",IF(P13=1,1,5)) | AK13: =IF(Q13="","",IF(Q13=1,1,5)) | AL13: =IF(O13="","",IF('分位数阈值'!$D$12="","",IFS(O13>='分位数阈值'!$D$12,5,O13>='分位数阈值'!$E$12,4,O13>='分位数阈值'!$F$12,3,O13>='分位数阈值'!$G$12,2,TRUE,1))) | AM13: =IF(R13="","",IF('分位数阈值'!$D$13="","",IFS(R13<='分位数阈值'!$G$13,5,R13<='分位数阈值'!$F$13,4,R13<='分位数阈值'!$E$13,3,R13<='分位数阈值'!$D$13,2,TRUE,1))) | AN13: =IF(S13="","",IF('分位数阈值'!$D$14="","",IFS(S13<='分位数阈值'!$G$14,5,S13<='分位数阈值'!$F$14,4,S13<='分位数阈值'!$E$14,3,S13<='分位数阈值'!$D$14,2,TRUE,1))) | AO13: =IF(T13="","",IF('分位数阈值'!$D$15="","",IFS(T13<='分位数阈值'!$G$15,5,T13<='分位数阈值'!$F$15,4,T13<='分位数阈值'!$E$15,3,T13<='分位数阈值'!$D$15,2,TRUE,1))) | AP13: =IF(U13="","",IF(U13=1,5,1)) | AQ13: =IF(V13="","",V13) | AR13: =IF(W13="","",IF('分位数阈值'!$D$16="","",IFS(W13<='分位数阈值'!$G$16,5,W13<='分位数阈值'!$F$16,4,W13<='分位数阈值'!$E$16,3,W13<='分位数阈值'!$D$16,2,TRUE,1))) | AS13: =IF(X13="","",X13) | AT13: =IF(Y13="","",Y13) | AU13: =IF($A13="","",IF(OR(Z13=1,AR13=1,AJ13=1),"淘汰","通过")) | AV13: =IF($A13="","",IF(OR(AA13=1,AR13=1,AND(AK13=1,AI13=1),AO13=1),"淘汰","通过")) | AW13: =IF($A13="","",IF(AU13="淘汰","",ROUND(SUMPRODUCT(Z13:AT13,Z$2:AT$2)/5,1))) | AX13: =IF($A13="","",IF(AV13="淘汰","",ROUND(SUMPRODUCT(Z13:AT13,Z$3:AT$3)/5,1)))
A14: OSK010 | B14: 大阪府大阪市生野区鶴橋二丁目 | C14: 34.664178 | D14: 135.53411 | E14: 9410 | F14: 116528 | G14: 0.7766 | H14: 0.5583 | I14: 0.8803 | J14: 0.7456 | K14: 0.1923 | L14: 4.39 | M14: 5 | N14: 17 | O14: 357 | P14: 1 | Q14: 1 | R14: 634 | S14: 411 | T14: 226 | U14: 0 | V14: 3 | W14: 24178 | X14: 4 | Y14: 4 | Z14: =IF(E14="","",IF('分位数阈值'!$D$2="","",IFS(E14>='分位数阈值'!$D$2,5,E14>='分位数阈值'!$E$2,4,E14>='分位数阈值'!$F$2,3,E14>='分位数阈值'!$G$2,2,TRUE,1))) | AA14: =IF(F14="","",IF('分位数阈值'!$D$3="","",IFS(F14>='分位数阈值'!$D$3,5,F14>='分位数阈值'!$E$3,4,F14>='分位数阈值'!$F$3,3,F14>='分位数阈值'!$G$3,2,TRUE,1))) | AB14: =IF(G14="","",IF('分位数阈值'!$D$4="","",IFS(G14>='分位数阈值'!$D$4,5,G14>='分位数阈值'!$E$4,4,G14>='分位数阈值'!$F$4,3,G14>='分位数阈值'!$G$4,2,TRUE,1))) | AC14: =IF(H14="","",IF('分位数阈值'!$D$5="","",IFS(H14>='分位数阈值'!$D$5,5,H14>='分位数阈值'!$E$5,4,H14>='分位数阈值'!$F$5,3,H14>='分位数阈值'!$G$5,2,TRUE,1))) | AD14: =IF(I14="","",IF('分位数阈值'!$D$6="","",IFS(I14>='分位数阈值'!$D$6,5,I14>='分位数阈值'!$E$6,4,I14>='分位数阈值'!$F$6,3,I14>='分位数阈值'!$G$6,2,TRUE,1))) | AE14: =IF(J14="","",IF('分位数阈值'!$D$7="","",IFS(J14>='分位数阈值'!$D$7,5,J14>='分位数阈值'!$E$7,4,J14>='分位数阈值'!$F$7,3,J14>='分位数阈值'!$G$7,2,TRUE,1))) | AF14: =IF(K14="","",IF('分位数阈值'!$D$8="","",IFS(K14>='分位数阈值'!$D$8,5,K14>='分位数阈值'!$E$8,4,K14>='分位数阈值'!$F$8,3,K14>='分位数阈值'!$G$8,2,TRUE,1))) | AG14: =IF(L14="","",IF('分位数阈值'!$D$9="","",IFS(L14>='分位数阈值'!$D$9,5,L14>='分位数阈值'!$E$9,4,L14>='分位数阈值'!$F$9,3,L14>='分位数阈值'!$G$9,2,TRUE,1))) | AH14: =IF(M14="","",IF('分位数阈值'!$D$10="","",IFS(M14<='分位数阈值'!$G$10,5,M14<='分位数阈值'!$F$10,4,M14<='分位数阈值'!$E$10,3,M14<='分位数阈值'!$D$10,2,TRUE,1))) | AI14: =IF(N14="","",IF('分位数阈值'!$D$11="","",IFS(N14<='分位数阈值'!$G$11,5,N14<='分位数阈值'!$F$11,4,N14<='分位数阈值'!$E$11,3,N14<='分位数阈值'!$D$11,2,TRUE,1))) | AJ14: =IF(P14="","",IF(P14=1,1,5)) | AK14: =IF(Q14="","",IF(Q14=1,1,5)) | AL14: =IF(O14="","",IF('分位数阈值'!$D$12="","",IFS(O14>='分位数阈值'!$D$12,5,O14>='分位数阈值'!$E$12,4,O14>='分位数阈值'!$F$12,3,O14>='分位数阈值'!$G$12,2,TRUE,1))) | AM14: =IF(R14="","",IF('分位数阈值'!$D$13="","",IFS(R14<='分位数阈值'!$G$13,5,R14<='分位数阈值'!$F$13,4,R14<='分位数阈值'!$E$13,3,R14<='分位数阈值'!$D$13,2,TRUE,1))) | AN14: =IF(S14="","",IF('分位数阈值'!$D$14="","",IFS(S14<='分位数阈值'!$G$14,5,S14<='分位数阈值'!$F$14,4,S14<='分位数阈值'!$E$14,3,S14<='分位数阈值'!$D$14,2,TRUE,1))) | AO14: =IF(T14="","",IF('分位数阈值'!$D$15="","",IFS(T14<='分位数阈值'!$G$15,5,T14<='分位数阈值'!$F$15,4,T14<='分位数阈值'!$E$15,3,T14<='分位数阈值'!$D$15,2,TRUE,1))) | AP14: =IF(U14="","",IF(U14=1,5,1)) | AQ14: =IF(V14="","",V14) | AR14: =IF(W14="","",IF('分位数阈值'!$D$16="","",IFS(W14<='分位数阈值'!$G$16,5,W14<='分位数阈值'!$F$16,4,W14<='分位数阈值'!$E$16,3,W14<='分位数阈值'!$D$16,2,TRUE,1))) | AS14: =IF(X14="","",X14) | AT14: =IF(Y14="","",Y14) | AU14: =IF($A14="","",IF(OR(Z14=1,AR14=1,AJ14=1),"淘汰","通过")) | AV14: =IF($A14="","",IF(OR(AA14=1,AR14=1,AND(AK14=1,AI14=1),AO14=1),"淘汰","通过")) | AW14: =IF($A14="","",IF(AU14="淘汰","",ROUND(SUMPRODUCT(Z14:AT14,Z$2:AT$2)/5,1))) | AX14: =IF($A14="","",IF(AV14="淘汰","",ROUND(SUMPRODUCT(Z14:AT14,Z$3:AT$3)/5,1)))
A15: OSK011 | B15: 大阪府大阪市阿倍野区阿倍野筋一丁目 | C15: 34.646604 | D15: 135.51097 | E15: 9561 | F15: 103008 | G15: 0.6869 | H15: 0.6485 | I15: 0.7541 | J15: 0.6752 | K15: 0.239 | L15: 2.62 | M15: 3 | N15: 17 | O15: 258 | P15: 0 | Q15: 0 | R15: 617 | S15: 242 | T15: 273 | U15: 1 | V15: 3 | W15: 25404 | X15: 3 | Y15: 3 | Z15: =IF(E15="","",IF('分位数阈值'!$D$2="","",IFS(E15>='分位数阈值'!$D$2,5,E15>='分位数阈值'!$E$2,4,E15>='分位数阈值'!$F$2,3,E15>='分位数阈值'!$G$2,2,TRUE,1))) | AA15: =IF(F15="","",IF('分位数阈值'!$D$3="","",IFS(F15>='分位数阈值'!$D$3,5,F15>='分位数阈值'!$E$3,4,F15>='分位数阈值'!$F$3,3,F15>='分位数阈值'!$G$3,2,TRUE,1))) | AB15: =IF(G15="","",IF('分位数阈值'!$D$4="","",IFS(G15>='分位数阈值'!$D$4,5,G15>='分位数阈值'!$E$4,4,G15>='分位数阈值'!$F$4,3,G15>='分位数阈值'!$G$4,2,TRUE,1))) | AC15: =IF(H15="","",IF('分位数阈值'!$D$5="","",IFS(H15>='分位数阈值'!$D$5,5,H15>='分位数阈值'!$E$5,4,H15>='分位数阈值'!$F$5,3,H15>='分位数阈值'!$G$5,2,TRUE,1))) | AD15: =IF(I15="","",IF('分位数阈值'!$D$6="","",IFS(I15>='分位数阈值'!$D$6,5,I15>='分位数阈值'!$E$6,4,I15>='分位数阈值'!$F$6,3,I15>='分位数阈值'!$G$6,2,TRUE,1))) | AE15: =IF(J15="","",IF('分位数阈值'!$D$7="","",IFS(J15>='分位数阈值'!$D$7,5,J15>='分位数阈值'!$E$7,4,J15>='分位数阈值'!$F$7,3,J15>='分位数阈值'!$G$7,2,TRUE,1))) | AF15: =IF(K15="","",IF('分位数阈值'!$D$8="","",IFS(K15>='分位数阈值'!$D$8,5,K15>='分位数阈值'!$E$8,4,K15>='分位数阈值'!$F$8,3,K15>='分位数阈值'!$G$8,2,TRUE,1))) | AG15: =IF(L15="","",IF('分位数阈值'!$D$9="","",IFS(L15>='分位数阈值'!$D$9,5,L15>='分位数阈值'!$E$9,4,L15>='分位数阈值'!$F$9,3,L15>='分位数阈值'!$G$9,2,TRUE,1))) | AH15: =IF(M15="","",IF('分位数阈值'!$D$10="","",IFS(M15<='分位数阈值'!$G$10,5,M15<='分位数阈值'!$F$10,4,M15<='分位数阈值'!$E$10,3,M15<='分位数阈值'!$D$10,2,TRUE,1))) | AI15: =IF(N15="","",IF('分位数阈值'!$D$11="","",IFS(N15<='分位数阈值'!$G$11,5,N15<='分位数阈值'!$F$11,4,N15<='分位数阈值'!$E$11,3,N15<='分位数阈值'!$D$11,2,TRUE,1))) | AJ15: =IF(P15="","",IF(P15=1,1,5)) | AK15: =IF(Q15="","",IF(Q15=1,1,5)) | AL15: =IF(O15="","",IF('分位数阈值'!$D$12="","",IFS(O15>='分位数阈值'!$D$12,5,O15>='分位数阈值'!$E$12,4,O15>='分位数阈值'!$F$12,3,O15>='分位数阈值'!$G$12,2,TRUE,1))) | AM15: =IF(R15="","",IF('分位数阈值'!$D$13="","",IFS(R15<='分位数阈值'!$G$13,5,R15<='分位数阈值'!$F$13,4,R15<='分位数阈值'!$E$13,3,R15<='分位数阈值'!$D$13,2,TRUE,1))) | AN15: =IF(S15="","",IF('分位数阈值'!$D$14="","",IFS(S15<='分位数阈值'!$G$14,5,S15<='分位数阈值'!$F$14,4,S15<='分位数阈值'!$E$14,3,S15<='分位数阈值'!$D$14,2,TRUE,1))) | AO15: =IF(T15="","",IF('分位数阈值'!$D$15="","",IFS(T15<='分位数阈值'!$G$15,5,T15<='分位数阈值'!$F$15,4,T15<='分位数阈值'!$E$15,3,T15<='分位数阈值'!$D$15,2,TRUE,1))) | AP15: =IF(U15="","",IF(U15=1,5,1)) | AQ15: =IF(V15="","",V15) | AR15: =IF(W15="","",IF('分位数阈值'!$D$16="","",IFS(W15<='分位数阈值'!$G$16,5,W15<='分位数阈值'!$F$16,4,W15<='分位数阈值'!$E$16,3,W15<='分位数阈值'!$D$16,2,TRUE,1))) | AS15: =IF(X15="","",X15) | AT15: =IF(Y15="","",Y15) | AU15: =IF($A15="","",IF(OR(Z15=1,AR15=1,AJ15=1),"淘汰","通过")) | AV15: =IF($A15="","",IF(OR(AA15=1,AR15=1,AND(AK15=1,AI15=1),AO15=1),"淘汰","通过")) | AW15: =IF($A15="","",IF(AU15="淘汰","",ROUND(SUMPRODUCT(Z15:AT15,Z$2:AT$2)/5,1))) | AX15: =IF($A15="","",IF(AV15="淘汰","",ROUND(SUMPRODUCT(Z15:AT15,Z$3:AT$3)/5,1)))
A16: OSK012 | B16: 大阪府大阪市住吉区長居東四丁目 | C16: 34.612122 | D16: 135.51608 | E16: 8750 | F16: 129907 | G16: 0.6492 | H16: 0.4147 | I16: 0.6139 | J16: 0.603 | K16: 0.292 | L16: 3.88 | M16: 3 | N16: 10 | O16: 384 | P16: 0 | Q16: 0 | R16: 909 | S16: 892 | T16: 434 | U16: 1 | V16: 4 | W16: 13593 | X16: 4 | Y16: 5 | Z16: =IF(E16="","",IF('分位数阈值'!$D$2="","",IFS(E16>='分位数阈值'!$D$2,5,E16>='分位数阈值'!$E$2,4,E16>='分位数阈值'!$F$2,3,E16>='分位数阈值'!$G$2,2,TRUE,1))) | AA16: =IF(F16="","",IF('分位数阈值'!$D$3="","",IFS(F16>='分位数阈值'!$D$3,5,F16>='分位数阈值'!$E$3,4,F16>='分位数阈值'!$F$3,3,F16>='分位数阈值'!$G$3,2,TRUE,1))) | AB16: =IF(G16="","",IF('分位数阈值'!$D$4="","",IFS(G16>='分位数阈值'!$D$4,5,G16>='分位数阈值'!$E$4,4,G16>='分位数阈值'!$F$4,3,G16>='分位数阈值'!$G$4,2,TRUE,1))) | AC16: =IF(H16="","",IF('分位数阈值'!$D$5="","",IFS(H16>='分位数阈值'!$D$5,5,H16>='分位数阈值'!$E$5,4,H16>='分位数阈值'!$F$5,3,H16>='分位数阈值'!$G$5,2,TRUE,1))) | AD16: =IF(I16="","",IF('分位数阈值'!$D$6="","",IFS(I16>='分位数阈值'!$D$6,5,I16>='分位数阈值'!$E$6,4,I16>='分位数阈值'!$F$6,3,I16>='分位数阈值'!$G$6,2,TRUE,1))) | AE16: =IF(J16="","",IF('分位数阈值'!$D$7="","",IFS(J16>='分位数阈值'!$D$7,5,J16>='分位数阈值'!$E$7,4,J16>='分位数阈值'!$F$7,3,J16>='分位数阈值'!$G$7,2,TRUE,1))) | AF16: =IF(K16="","",IF('分位数阈值'!$D$8="","",IFS(K16>='分位数阈值'!$D$8,5,K16>='分位数阈值'!$E$8,4,K16>='分位数阈值'!$F$8,3,K16>='分位数阈值'!$G$8,2,TRUE,1))) | AG16: =IF(L16="","",IF('分位数阈值'!$D$9="","",IFS(L16>='分位数阈值'!$D$9,5,L16>='分位数阈值'!$E$9,4,L16>='分位数阈值'!$F$9,3,L16>='分位数阈值'!$G$9,2,TRUE,1))) | AH16: =IF(M16="","",IF('分位数阈值'!$D$10="","",IFS(M16<='分位数阈值'!$G$10,5,M16<='分位数阈值'!$F$10,4,M16<='分位数阈值'!$E$10,3,M16<='分位数阈值'!$D$10,2,TRUE,1))) | AI16: =IF(N16="","",IF('分位数阈值'!$D$11="","",IFS(N16<='分位数阈值'!$G$11,5,N16<='分位数阈值'!$F$11,4,N16<='分位数阈值'!$E$11,3,N16<='分位数阈值'!$D$11,2,TRUE,1))) | AJ16: =IF(P16="","",IF(P16=1,1,5)) | AK16: =IF(Q16="","",IF(Q16=1,1,5)) | AL16: =IF(O16="","",IF('分位数阈值'!$D$12="","",IFS(O16>='分位数阈值'!$D$12,5,O16>='分位数阈值'!$E$12,4,O16>='分位数阈值'!$F$12,3,O16>='分位数阈值'!$G$12,2,TRUE,1))) | AM16: =IF(R16="","",IF('分位数阈值'!$D$13="","",IFS(R16<='分位数阈值'!$G$13,5,R16<='分位数阈值'!$F$13,4,R16<='分位数阈值'!$E$13,3,R16<='分位数阈值'!$D$13,2,TRUE,1))) | AN16: =IF(S16="","",IF('分位数阈值'!$D$14="","",IFS(S16<='分位数阈值'!$G$14,5,S16<='分位数阈值'!$F$14,4,S16<='分位数阈值'!$E$14,3,S16<='分位数阈值'!$D$14,2,TRUE,1))) | AO16: =IF(T16="","",IF('分位数阈值'!$D$15="","",IFS(T16<='分位数阈值'!$G$15,5,T16<='分位数阈值'!$F$15,4,T16<='分位数阈值'!$E$15,3,T16<='分位数阈值'!$D$15,2,TRUE,1))) | AP16: =IF(U16="","",IF(U16=1,5,1)) | AQ16: =IF(V16="","",V16) | AR16: =IF(W16="","",IF('分位数阈值'!$D$16="","",IFS(W16<='分位数阈值'!$G$16,5,W16<='分位数阈值'!$F$16,4,W16<='分位数阈值'!$E$16,3,W16<='分位数阈值'!$D$16,2,TRUE,1))) | AS16: =IF(X16="","",X16) | AT16: =IF(Y16="","",Y16) | AU16: =IF($A16="","",IF(OR(Z16=1,AR16=1,AJ16=1),"淘汰","通过")) | AV16: =IF($A16="","",IF(OR(AA16=1,AR16=1,AND(AK16=1,AI16=1),AO16=1),"淘汰","通过")) | AW16: =IF($A16="","",IF(AU16="淘汰","",ROUND(SUMPRODUCT(Z16:AT16,Z$2:AT$2)/5,1))) | AX16: =IF($A16="","",IF(AV16="淘汰","",ROUND(SUMPRODUCT(Z16:AT16,Z$3:AT$3)/5,1)))
... A24: OSK020 | B24: 大阪府大阪市港区弁天一丁目 | C24: 34.672304 | D24: 135.46046 | E24: 14938 | F24: 121952 | G24: 0.7343 | H24: 0.6469 | I24: 0.9272 | J24: 0.775 | K24: 0.245 | L24: 4.23 | M24: 3 | N24: 19 | O24: 287 | P24: 0 | Q24: 0 | R24: 599 | S24: 485 | T24: 208 | U24: 1 | V24: 3 | W24: 24927 | X24: 4 | Y24: 4 | Z24: =IF(E24="","",IF('分位数阈值'!$D$2="","",IFS(E24>='分位数阈值'!$D$2,5,E24>='分位数阈值'!$E$2,4,E24>='分位数阈值'!$F$2,3,E24>='分位数阈值'!$G$2,2,TRUE,1))) | AA24: =IF(F24="","",IF('分位数阈值'!$D$3="","",IFS(F24>='分位数阈值'!$D$3,5,F24>='分位数阈值'!$E$3,4,F24>='分位数阈值'!$F$3,3,F24>='分位数阈值'!$G$3,2,TRUE,1))) | AB24: =IF(G24="","",IF('分位数阈值'!$D$4="","",IFS(G24>='分位数阈值'!$D$4,5,G24>='分位数阈值'!$E$4,4,G24>='分位数阈值'!$F$4,3,G24>='分位数阈值'!$G$4,2,TRUE,1))) | AC24: =IF(H24="","",IF('分位数阈值'!$D$5="","",IFS(H24>='分位数阈值'!$D$5,5,H24>='分位数阈值'!$E$5,4,H24>='分位数阈值'!$F$5,3,H24>='分位数阈值'!$G$5,2,TRUE,1))) | AD24: =IF(I24="","",IF('分位数阈值'!$D$6="","",IFS(I24>='分位数阈值'!$D$6,5,I24>='分位数阈值'!$E$6,4,I24>='分位数阈值'!$F$6,3,I24>='分位数阈值'!$G$6,2,TRUE,1))) | AE24: =IF(J24="","",IF('分位数阈值'!$D$7="","",IFS(J24>='分位数阈值'!$D$7,5,J24>='分位数阈值'!$E$7,4,J24>='分位数阈值'!$F$7,3,J24>='分位数阈值'!$G$7,2,TRUE,1))) | AF24: =IF(K24="","",IF('分位数阈值'!$D$8="","",IFS(K24>='分位数阈值'!$D$8,5,K24>='分位数阈值'!$E$8,4,K24>='分位数阈值'!$F$8,3,K24>='分位数阈值'!$G$8,2,TRUE,1))) | AG24: =IF(L24="","",IF('分位数阈值'!$D$9="","",IFS(L24>='分位数阈值'!$D$9,5,L24>='分位数阈值'!$E$9,4,L24>='分位数阈值'!$F$9,3,L24>='分位数阈值'!$G$9,2,TRUE,1))) | AH24: =IF(M24="","",IF('分位数阈值'!$D$10="","",IFS(M24<='分位数阈值'!$G$10,5,M24<='分位数阈值'!$F$10,4,M24<='分位数阈值'!$E$10,3,M24<='分位数阈值'!$D$10,2,TRUE,1))) | AI24: =IF(N24="","",IF('分位数阈值'!$D$11="","",IFS(N24<='分位数阈值'!$G$11,5,N24<='分位数阈值'!$F$11,4,N24<='分位数阈值'!$E$11,3,N24<='分位数阈值'!$D$11,2,TRUE,1))) | AJ24: =IF(P24="","",IF(P24=1,1,5)) | AK24: =IF(Q24="","",IF(Q24=1,1,5)) | AL24: =IF(O24="","",IF('分位数阈值'!$D$12="","",IFS(O24>='分位数阈值'!$D$12,5,O24>='分位数阈值'!$E$12,4,O24>='分位数阈值'!$F$12,3,O24>='分位数阈值'!$G$12,2,TRUE,1))) | AM24: =IF(R24="","",IF('分位数阈值'!$D$13="","",IFS(R24<='分位数阈值'!$G$13,5,R24<='分位数阈值'!$F$13,4,R24<='分位数阈值'!$E$13,3,R24<='分位数阈值'!$D$13,2,TRUE,1))) | AN24: =IF(S24="","",IF('分位数阈值'!$D$14="","",IFS(S24<='分位数阈值'!$G$14,5,S24<='分位数阈值'!$F$14,4,S24<='分位数阈值'!$E$14,3,S24<='分位数阈值'!$D$14,2,TRUE,1))) | AO24: =IF(T24="","",IF('分位数阈值'!$D$15="","",IFS(T24<='分位数阈值'!$G$15,5,T24<='分位数阈值'!$F$15,4,T24<='分位数阈值'!$E$15,3,T24<='分位数阈值'!$D$15,2,TRUE,1))) | AP24: =IF(U24="","",IF(U24=1,5,1)) | AQ24: =IF(V24="","",V24) | AR24: =IF(W24="","",IF('分位数阈值'!$D$16="","",IFS(W24<='分位数阈值'!$G$16,5,W24<='分位数阈值'!$F$16,4,W24<='分位数阈值'!$E$16,3,W24<='分位数阈值'!$D$16,2,TRUE,1))) | AS24: =IF(X24="","",X24) | AT24: =IF(Y24="","",Y24) | AU24: =IF($A24="","",IF(OR(Z24=1,AR24=1,AJ24=1),"淘汰","通过")) | AV24: =IF($A24="","",IF(OR(AA24=1,AR24=1,AND(AK24=1,AI24=1),AO24=1),"淘汰","通过")) | AW24: =IF($A24="","",IF(AU24="淘汰","",ROUND(SUMPRODUCT(Z24:AT24,Z$2:AT$2)/5,1))) | AX24: =IF($A24="","",IF(AV24="淘汰","",ROUND(SUMPRODUCT(Z24:AT24,Z$3:AT$3)/5,1)))
Z25: =IF(E25="","",IF('分位数阈值'!$D$2="","",IFS(E25>='分位数阈值'!$D$2,5,E25>='分位数阈值'!$E$2,4,E25>='分位数阈值'!$F$2,3,E25>='分位数阈值'!$G$2,2,TRUE,1))) | AA25: =IF(F25="","",IF('分位数阈值'!$D$3="","",IFS(F25>='分位数阈值'!$D$3,5,F25>='分位数阈值'!$E$3,4,F25>='分位数阈值'!$F$3,3,F25>='分位数阈值'!$G$3,2,TRUE,1))) | AB25: =IF(G25="","",IF('分位数阈值'!$D$4="","",IFS(G25>='分位数阈值'!$D$4,5,G25>='分位数阈值'!$E$4,4,G25>='分位数阈值'!$F$4,3,G25>='分位数阈值'!$G$4,2,TRUE,1))) | AC25: =IF(H25="","",IF('分位数阈值'!$D$5="","",IFS(H25>='分位数阈值'!$D$5,5,H25>='分位数阈值'!$E$5,4,H25>='分位数阈值'!$F$5,3,H25>='分位数阈值'!$G$5,2,TRUE,1))) | AD25: =IF(I25="","",IF('分位数阈值'!$D$6="","",IFS(I25>='分位数阈值'!$D$6,5,I25>='分位数阈值'!$E$6,4,I25>='分位数阈值'!$F$6,3,I25>='分位数阈值'!$G$6,2,TRUE,1))) | AE25: =IF(J25="","",IF('分位数阈值'!$D$7="","",IFS(J25>='分位数阈值'!$D$7,5,J25>='分位数阈值'!$E$7,4,J25>='分位数阈值'!$F$7,3,J25>='分位数阈值'!$G$7,2,TRUE,1))) | AF25: =IF(K25="","",IF('分位数阈值'!$D$8="","",IFS(K25>='分位数阈值'!$D$8,5,K25>='分位数阈值'!$E$8,4,K25>='分位数阈值'!$F$8,3,K25>='分位数阈值'!$G$8,2,TRUE,1))) | AG25: =IF(L25="","",IF('分位数阈值'!$D$9="","",IFS(L25>='分位数阈值'!$D$9,5,L25>='分位数阈值'!$E$9,4,L25>='分位数阈值'!$F$9,3,L25>='分位数阈值'!$G$9,2,TRUE,1))) | AH25: =IF(M25="","",IF('分位数阈值'!$D$10="","",IFS(M25<='分位数阈值'!$G$10,5,M25<='分位数阈值'!$F$10,4,M25<='分位数阈值'!$E$10,3,M25<='分位数阈值'!$D$10,2,TRUE,1))) | AI25: =IF(N25="","",IF('分位数阈值'!$D$11="","",IFS(N25<='分位数阈值'!$G$11,5,N25<='分位数阈值'!$F$11,4,N25<='分位数阈值'!$E$11,3,N25<='分位数阈值'!$D$11,2,TRUE,1))) | AJ25: =IF(P25="","",IF(P25=1,1,5)) | AK25: =IF(Q25="","",IF(Q25=1,1,5)) | AL25: =IF(O25="","",IF('分位数阈值'!$D$12="","",IFS(O25>='分位数阈值'!$D$12,5,O25>='分位数阈值'!$E$12,4,O25>='分位数阈值'!$F$12,3,O25>='分位数阈值'!$G$12,2,TRUE,1))) | AM25: =IF(R25="","",IF('分位数阈值'!$D$13="","",IFS(R25<='分位数阈值'!$G$13,5,R25<='分位数阈值'!$F$13,4,R25<='分位数阈值'!$E$13,3,R25<='分位数阈值'!$D$13,2,TRUE,1))) | AN25: =IF(S25="","",IF('分位数阈值'!$D$14="","",IFS(S25<='分位数阈值'!$G$14,5,S25<='分位数阈值'!$F$14,4,S25<='分位数阈值'!$E$14,3,S25<='分位数阈值'!$D$14,2,TRUE,1))) | AO25: =IF(T25="","",IF('分位数阈值'!$D$15="","",IFS(T25<='分位数阈值'!$G$15,5,T25<='分位数阈值'!$F$15,4,T25<='分位数阈值'!$E$15,3,T25<='分位数阈值'!$D$15,2,TRUE,1))) | AP25: =IF(U25="","",IF(U25=1,5,1)) | AQ25: =IF(V25="","",V25) | AR25: =IF(W25="","",IF('分位数阈值'!$D$16="","",IFS(W25<='分位数阈值'!$G$16,5,W25<='分位数阈值'!$F$16,4,W25<='分位数阈值'!$E$16,3,W25<='分位数阈值'!$D$16,2,TRUE,1))) | AS25: =IF(X25="","",X25) | AT25: =IF(Y25="","",Y25) | AU25: =IF($A25="","",IF(OR(Z25=1,AR25=1,AJ25=1),"淘汰","通过")) | AV25: =IF($A25="","",IF(OR(AA25=1,AR25=1,AND(AK25=1,AI25=1),AO25=1),"淘汰","通过")) | AW25: =IF($A25="","",IF(AU25="淘汰","",ROUND(SUMPRODUCT(Z25:AT25,Z$2:AT$2)/5,1))) | AX25: =IF($A25="","",IF(AV25="淘汰","",ROUND(SUMPRODUCT(Z25:AT25,Z$3:AT$3)/5,1)))
Z26: =IF(E26="","",IF('分位数阈值'!$D$2="","",IFS(E26>='分位数阈值'!$D$2,5,E26>='分位数阈值'!$E$2,4,E26>='分位数阈值'!$F$2,3,E26>='分位数阈值'!$G$2,2,TRUE,1))) | AA26: =IF(F26="","",IF('分位数阈值'!$D$3="","",IFS(F26>='分位数阈值'!$D$3,5,F26>='分位数阈值'!$E$3,4,F26>='分位数阈值'!$F$3,3,F26>='分位数阈值'!$G$3,2,TRUE,1))) | AB26: =IF(G26="","",IF('分位数阈值'!$D$4="","",IFS(G26>='分位数阈值'!$D$4,5,G26>='分位数阈值'!$E$4,4,G26>='分位数阈值'!$F$4,3,G26>='分位数阈值'!$G$4,2,TRUE,1))) | AC26: =IF(H26="","",IF('分位数阈值'!$D$5="","",IFS(H26>='分位数阈值'!$D$5,5,H26>='分位数阈值'!$E$5,4,H26>='分位数阈值'!$F$5,3,H26>='分位数阈值'!$G$5,2,TRUE,1))) | AD26: =IF(I26="","",IF('分位数阈值'!$D$6="","",IFS(I26>='分位数阈值'!$D$6,5,I26>='分位数阈值'!$E$6,4,I26>='分位数阈值'!$F$6,3,I26>='分位数阈值'!$G$6,2,TRUE,1))) | AE26: =IF(J26="","",IF('分位数阈值'!$D$7="","",IFS(J26>='分位数阈值'!$D$7,5,J26>='分位数阈值'!$E$7,4,J26>='分位数阈值'!$F$7,3,J26>='分位数阈值'!$G$7,2,TRUE,1))) | AF26: =IF(K26="","",IF('分位数阈值'!$D$8="","",IFS(K26>='分位数阈值'!$D$8,5,K26>='分位数阈值'!$E$8,4,K26>='分位数阈值'!$F$8,3,K26>='分位数阈值'!$G$8,2,TRUE,1))) | AG26: =IF(L26="","",IF('分位数阈值'!$D$9="","",IFS(L26>='分位数阈值'!$D$9,5,L26>='分位数阈值'!$E$9,4,L26>='分位数阈值'!$F$9,3,L26>='分位数阈值'!$G$9,2,TRUE,1))) | AH26: =IF(M26="","",IF('分位数阈值'!$D$10="","",IFS(M26<='分位数阈值'!$G$10,5,M26<='分位数阈值'!$F$10,4,M26<='分位数阈值'!$E$10,3,M26<='分位数阈值'!$D$10,2,TRUE,1))) | AI26: =IF(N26="","",IF('分位数阈值'!$D$11="","",IFS(N26<='分位数阈值'!$G$11,5,N26<='分位数阈值'!$F$11,4,N26<='分位数阈值'!$E$11,3,N26<='分位数阈值'!$D$11,2,TRUE,1))) | AJ26: =IF(P26="","",IF(P26=1,1,5)) | AK26: =IF(Q26="","",IF(Q26=1,1,5)) | AL26: =IF(O26="","",IF('分位数阈值'!$D$12="","",IFS(O26>='分位数阈值'!$D$12,5,O26>='分位数阈值'!$E$12,4,O26>='分位数阈值'!$F$12,3,O26>='分位数阈值'!$G$12,2,TRUE,1))) | AM26: =IF(R26="","",IF('分位数阈值'!$D$13="","",IFS(R26<='分位数阈值'!$G$13,5,R26<='分位数阈值'!$F$13,4,R26<='分位数阈值'!$E$13,3,R26<='分位数阈值'!$D$13,2,TRUE,1))) | AN26: =IF(S26="","",IF('分位数阈值'!$D$14="","",IFS(S26<='分位数阈值'!$G$14,5,S26<='分位数阈值'!$F$14,4,S26<='分位数阈值'!$E$14,3,S26<='分位数阈值'!$D$14,2,TRUE,1))) | AO26: =IF(T26="","",IF('分位数阈值'!$D$15="","",IFS(T26<='分位数阈值'!$G$15,5,T26<='分位数阈值'!$F$15,4,T26<='分位数阈值'!$E$15,3,T26<='分位数阈值'!$D$15,2,TRUE,1))) | AP26: =IF(U26="","",IF(U26=1,5,1)) | AQ26: =IF(V26="","",V26) | AR26: =IF(W26="","",IF('分位数阈值'!$D$16="","",IFS(W26<='分位数阈值'!$G$16,5,W26<='分位数阈值'!$F$16,4,W26<='分位数阈值'!$E$16,3,W26<='分位数阈值'!$D$16,2,TRUE,1))) | AS26: =IF(X26="","",X26) | AT26: =IF(Y26="","",Y26) | AU26: =IF($A26="","",IF(OR(Z26=1,AR26=1,AJ26=1),"淘汰","通过")) | AV26: =IF($A26="","",IF(OR(AA26=1,AR26=1,AND(AK26=1,AI26=1),AO26=1),"淘汰","通过")) | AW26: =IF($A26="","",IF(AU26="淘汰","",ROUND(SUMPRODUCT(Z26:AT26,Z$2:AT$2)/5,1))) | AX26: =IF($A26="","",IF(AV26="淘汰","",ROUND(SUMPRODUCT(Z26:AT26,Z$3:AT$3)/5,1)))
Z27: =IF(E27="","",IF('分位数阈值'!$D$2="","",IFS(E27>='分位数阈值'!$D$2,5,E27>='分位数阈值'!$E$2,4,E27>='分位数阈值'!$F$2,3,E27>='分位数阈值'!$G$2,2,TRUE,1))) | AA27: =IF(F27="","",IF('分位数阈值'!$D$3="","",IFS(F27>='分位数阈值'!$D$3,5,F27>='分位数阈值'!$E$3,4,F27>='分位数阈值'!$F$3,3,F27>='分位数阈值'!$G$3,2,TRUE,1))) | AB27: =IF(G27="","",IF('分位数阈值'!$D$4="","",IFS(G27>='分位数阈值'!$D$4,5,G27>='分位数阈值'!$E$4,4,G27>='分位数阈值'!$F$4,3,G27>='分位数阈值'!$G$4,2,TRUE,1))) | AC27: =IF(H27="","",IF('分位数阈值'!$D$5="","",IFS(H27>='分位数阈值'!$D$5,5,H27>='分位数阈值'!$E$5,4,H27>='分位数阈值'!$F$5,3,H27>='分位数阈值'!$G$5,2,TRUE,1))) | AD27: =IF(I27="","",IF('分位数阈值'!$D$6="","",IFS(I27>='分位数阈值'!$D$6,5,I27>='分位数阈值'!$E$6,4,I27>='分位数阈值'!$F$6,3,I27>='分位数阈值'!$G$6,2,TRUE,1))) | AE27: =IF(J27="","",IF('分位数阈值'!$D$7="","",IFS(J27>='分位数阈值'!$D$7,5,J27>='分位数阈值'!$E$7,4,J27>='分位数阈值'!$F$7,3,J27>='分位数阈值'!$G$7,2,TRUE,1))) | AF27: =IF(K27="","",IF('分位数阈值'!$D$8="","",IFS(K27>='分位数阈值'!$D$8,5,K27>='分位数阈值'!$E$8,4,K27>='分位数阈值'!$F$8,3,K27>='分位数阈值'!$G$8,2,TRUE,1))) | AG27: =IF(L27="","",IF('分位数阈值'!$D$9="","",IFS(L27>='分位数阈值'!$D$9,5,L27>='分位数阈值'!$E$9,4,L27>='分位数阈值'!$F$9,3,L27>='分位数阈值'!$G$9,2,TRUE,1))) | AH27: =IF(M27="","",IF('分位数阈值'!$D$10="","",IFS(M27<='分位数阈值'!$G$10,5,M27<='分位数阈值'!$F$10,4,M27<='分位数阈值'!$E$10,3,M27<='分位数阈值'!$D$10,2,TRUE,1))) | AI27: =IF(N27="","",IF('分位数阈值'!$D$11="","",IFS(N27<='分位数阈值'!$G$11,5,N27<='分位数阈值'!$F$11,4,N27<='分位数阈值'!$E$11,3,N27<='分位数阈值'!$D$11,2,TRUE,1))) | AJ27: =IF(P27="","",IF(P27=1,1,5)) | AK27: =IF(Q27="","",IF(Q27=1,1,5)) | AL27: =IF(O27="","",IF('分位数阈值'!$D$12="","",IFS(O27>='分位数阈值'!$D$12,5,O27>='分位数阈值'!$E$12,4,O27>='分位数阈值'!$F$12,3,O27>='分位数阈值'!$G$12,2,TRUE,1))) | AM27: =IF(R27="","",IF('分位数阈值'!$D$13="","",IFS(R27<='分位数阈值'!$G$13,5,R27<='分位数阈值'!$F$13,4,R27<='分位数阈值'!$E$13,3,R27<='分位数阈值'!$D$13,2,TRUE,1))) | AN27: =IF(S27="","",IF('分位数阈值'!$D$14="","",IFS(S27<='分位数阈值'!$G$14,5,S27<='分位数阈值'!$F$14,4,S27<='分位数阈值'!$E$14,3,S27<='分位数阈值'!$D$14,2,TRUE,1))) | AO27: =IF(T27="","",IF('分位数阈值'!$D$15="","",IFS(T27<='分位数阈值'!$G$15,5,T27<='分位数阈值'!$F$15,4,T27<='分位数阈值'!$E$15,3,T27<='分位数阈值'!$D$15,2,TRUE,1))) | AP27: =IF(U27="","",IF(U27=1,5,1)) | AQ27: =IF(V27="","",V27) | AR27: =IF(W27="","",IF('分位数阈值'!$D$16="","",IFS(W27<='分位数阈值'!$G$16,5,W27<='分位数阈值'!$F$16,4,W27<='分位数阈值'!$E$16,3,W27<='分位数阈值'!$D$16,2,TRUE,1))) | AS27: =IF(X27="","",X27) | AT27: =IF(Y27="","",Y27) | AU27: =IF($A27="","",IF(OR(Z27=1,AR27=1,AJ27=1),"淘汰","通过")) | AV27: =IF($A27="","",IF(OR(AA27=1,AR27=1,AND(AK27=1,AI27=1),AO27=1),"淘汰","通过")) | AW27: =IF($A27="","",IF(AU27="淘汰","",ROUND(SUMPRODUCT(Z27:AT27,Z$2:AT$2)/5,1))) | AX27: =IF($A27="","",IF(AV27="淘汰","",ROUND(SUMPRODUCT(Z27:AT27,Z$3:AT$3)/5,1)))
Z28: =IF(E28="","",IF('分位数阈值'!$D$2="","",IFS(E28>='分位数阈值'!$D$2,5,E28>='分位数阈值'!$E$2,4,E28>='分位数阈值'!$F$2,3,E28>='分位数阈值'!$G$2,2,TRUE,1))) | AA28: =IF(F28="","",IF('分位数阈值'!$D$3="","",IFS(F28>='分位数阈值'!$D$3,5,F28>='分位数阈值'!$E$3,4,F28>='分位数阈值'!$F$3,3,F28>='分位数阈值'!$G$3,2,TRUE,1))) | AB28: =IF(G28="","",IF('分位数阈值'!$D$4="","",IFS(G28>='分位数阈值'!$D$4,5,G28>='分位数阈值'!$E$4,4,G28>='分位数阈值'!$F$4,3,G28>='分位数阈值'!$G$4,2,TRUE,1))) | AC28: =IF(H28="","",IF('分位数阈值'!$D$5="","",IFS(H28>='分位数阈值'!$D$5,5,H28>='分位数阈值'!$E$5,4,H28>='分位数阈值'!$F$5,3,H28>='分位数阈值'!$G$5,2,TRUE,1))) | AD28: =IF(I28="","",IF('分位数阈值'!$D$6="","",IFS(I28>='分位数阈值'!$D$6,5,I28>='分位数阈值'!$E$6,4,I28>='分位数阈值'!$F$6,3,I28>='分位数阈值'!$G$6,2,TRUE,1))) | AE28: =IF(J28="","",IF('分位数阈值'!$D$7="","",IFS(J28>='分位数阈值'!$D$7,5,J28>='分位数阈值'!$E$7,4,J28>='分位数阈值'!$F$7,3,J28>='分位数阈值'!$G$7,2,TRUE,1))) | AF28: =IF(K28="","",IF('分位数阈值'!$D$8="","",IFS(K28>='分位数阈值'!$D$8,5,K28>='分位数阈值'!$E$8,4,K28>='分位数阈值'!$F$8,3,K28>='分位数阈值'!$G$8,2,TRUE,1))) | AG28: =IF(L28="","",IF('分位数阈值'!$D$9="","",IFS(L28>='分位数阈值'!$D$9,5,L28>='分位数阈值'!$E$9,4,L28>='分位数阈值'!$F$9,3,L28>='分位数阈值'!$G$9,2,TRUE,1))) | AH28: =IF(M28="","",IF('分位数阈值'!$D$10="","",IFS(M28<='分位数阈值'!$G$10,5,M28<='分位数阈值'!$F$10,4,M28<='分位数阈值'!$E$10,3,M28<='分位数阈值'!$D$10,2,TRUE,1))) | AI28: =IF(N28="","",IF('分位数阈值'!$D$11="","",IFS(N28<='分位数阈值'!$G$11,5,N28<='分位数阈值'!$F$11,4,N28<='分位数阈值'!$E$11,3,N28<='分位数阈值'!$D$11,2,TRUE,1))) | AJ28: =IF(P28="","",IF(P28=1,1,5)) | AK28: =IF(Q28="","",IF(Q28=1,1,5)) | AL28: =IF(O28="","",IF('分位数阈值'!$D$12="","",IFS(O28>='分位数阈值'!$D$12,5,O28>='分位数阈值'!$E$12,4,O28>='分位数阈值'!$F$12,3,O28>='分位数阈值'!$G$12,2,TRUE,1))) | AM28: =IF(R28="","",IF('分位数阈值'!$D$13="","",IFS(R28<='分位数阈值'!$G$13,5,R28<='分位数阈值'!$F$13,4,R28<='分位数阈值'!$E$13,3,R28<='分位数阈值'!$D$13,2,TRUE,1))) | AN28: =IF(S28="","",IF('分位数阈值'!$D$14="","",IFS(S28<='分位数阈值'!$G$14,5,S28<='分位数阈值'!$F$14,4,S28<='分位数阈值'!$E$14,3,S28<='分位数阈值'!$D$14,2,TRUE,1))) | AO28: =IF(T28="","",IF('分位数阈值'!$D$15="","",IFS(T28<='分位数阈值'!$G$15,5,T28<='分位数阈值'!$F$15,4,T28<='分位数阈值'!$E$15,3,T28<='分位数阈值'!$D$15,2,TRUE,1))) | AP28: =IF(U28="","",IF(U28=1,5,1)) | AQ28: =IF(V28="","",V28) | AR28: =IF(W28="","",IF('分位数阈值'!$D$16="","",IFS(W28<='分位数阈值'!$G$16,5,W28<='分位数阈值'!$F$16,4,W28<='分位数阈值'!$E$16,3,W28<='分位数阈值'!$D$16,2,TRUE,1))) | AS28: =IF(X28="","",X28) | AT28: =IF(Y28="","",Y28) | AU28: =IF($A28="","",IF(OR(Z28=1,AR28=1,AJ28=1),"淘汰","通过")) | AV28: =IF($A28="","",IF(OR(AA28=1,AR28=1,AND(AK28=1,AI28=1),AO28=1),"淘汰","通过")) | AW28: =IF($A28="","",IF(AU28="淘汰","",ROUND(SUMPRODUCT(Z28:AT28,Z$2:AT$2)/5,1))) | AX28: =IF($A28="","",IF(AV28="淘汰","",ROUND(SUMPRODUCT(Z28:AT28,Z$3:AT$3)/5,1)))
